<?xml version="1.0" ?>
<!-- =================================================================================== -->
<!-- |    This document was autogenerated by xacro from reemc_full_ft_hey5.urdf.xacro  | -->
<!-- |    EDITING THIS FILE BY HAND IS NOT RECOMMENDED                                 | -->
<!-- =================================================================================== -->
<!--

  Copyright (c) 2014, PAL Robotics, S.L.
  All rights reserved.

  This work is licensed under the Creative Commons Attribution-NonCommercial-NoDerivs 3.0 Unported License.
  To view a copy of this license, visit http://creativecommons.org/licenses/by-nc-nd/3.0/ or send a letter to
  Creative Commons, 444 Castro Street, Suite 900, Mountain View, California, 94041, USA.
-->
<robot name="reemc" xmlns:controller="http://playerstage.sourceforge.net/gazebo/xmlschema/#controller" xmlns:interface="http://playerstage.sourceforge.net/gazebo/xmlschema/#interface" xmlns:sensor="http://playerstage.sourceforge.net/gazebo/xmlschema/#sensor" xmlns:xacro="http://www.ros.org/wiki/xacro">
  
  <link name="world"/>

  <joint name="base_link_TX_joint" type="prismatic">
    <parent link="world"/>
    <child link="base_link_TX"/>
    <axis xyz="1 0 0"/>
    <origin xyz="0 0 0"/>
    <limit effort="1000.0" lower="-10.0" upper="10.0" velocity="10.0"/>
  </joint>

  <link name="base_link_TX"/>

  <joint name="base_link_TY_joint" type="prismatic">
    <parent link="base_link_TX"/>
    <child link="base_link_TY"/>
    <axis xyz="0 1 0"/>
    <origin xyz="0 0 0"/>
    <limit effort="1000.0" lower="-10.0" upper="10.0" velocity="10.0"/>
  </joint>

  <link name="base_link_TY"/>

  <joint name="base_link_TZ_joint" type="prismatic">
    <parent link="base_link_TY"/>
    <child link="base_link_TZ"/>
    <axis xyz="0 0 1"/>
    <origin xyz="0 0 0"/>
    <limit effort="1000.0" lower="0.0" upper="10.0" velocity="10.0"/>
  </joint>

  <link name="base_link_TZ"/>

  <joint name="base_link_RX_joint" type="revolute">
    <parent link="base_link_TZ"/>
    <child link="base_link_RX"/>
    <axis xyz="1 0 0"/>
    <origin xyz="0 0 0"/>
    <limit effort="1000.0" lower="-1.57079" upper="1.57079" velocity="10.0"/>
  </joint>

  <link name="base_link_RX"/>

  <joint name="base_link_RY_joint" type="revolute">
    <parent link="base_link_RX"/>
    <child link="base_link_RY"/>
    <axis xyz="0 1 0"/>
    <origin xyz="0 0 0"/>
    <limit effort="1000.0" lower="-1.57079" upper="1.57079" velocity="10.0"/>
  </joint>

  <link name="base_link_RY"/>

  <joint name="base_link_RZ_joint" type="revolute">
    <parent link="base_link_RY"/>
    <child link="base_link"/>
    <axis xyz="0 0 1"/>
    <origin xyz="0 0 0"/>
    <limit effort="1000.0" lower="-3.1416" upper="3.1416" velocity="10.0"/>
  </joint>

  <link name="base_link">
    <inertial>
      <mass value="15.525846"/>
      <origin rpy="0 0 0" xyz="-0.01209 -0.00442 0.02145"/>
      <inertia ixx="0.03408839175" ixy="0.00000898087" ixz="0.00238269732" iyy="0.03351929137" iyz="0.00049460232" izz="0.04506059363"/>
    </inertial>
    <visual>
      <origin rpy="0 0 0" xyz="0 0 0"/>
      <geometry>
        <mesh filename="package://tum_ics_h1_description/meshes/base/base.dae"/>
      </geometry>
      <material name="LightGrey"/>
    </visual>
    <collision>
      <origin rpy="0 0 0" xyz="-0.022 0 0.01"/>
      <geometry>
        <box size="0.3 0.35 0.14"/>
      </geometry>
    </collision>
  </link>
  <!-- TODO: Update dynamic models -->
  <!-- TODO: Update dynamic models -->
  <material name="Hey5DarkGrey">
    <color rgba="0.1 0.1 0.1 1.0"/>
  </material>
  <!--TODO: Check-->
  <gazebo>
    <plugin filename="libgazebo_ros_control.so" name="gazebo_ros_control">
      <ns/>
      <!-- <robotSimType>reemc_hardware_gazebo/ReemcHardwareGazebo</robotSimType> -->
      <robotSimType>pal_hardware_gazebo/PalHardwareGazebo</robotSimType>
      <robotNamespace/>
      <controlPeriod>0.001</controlPeriod>
    </plugin>
    <plugin filename="libgazebo_ros_p3d.so" name="gazebo_ros_p3d">
      <bodyName>base_link</bodyName>
      <topicName>ground_truth_odom</topicName>
      <alwaysOn>true</alwaysOn>
      <updateRate>100.0</updateRate>
    </plugin>
  </gazebo>
  <gazebo>
    <plugin filename="libgazebo_ros_force.so" name="gazebo_ros_force">
      <bodyName>base_link</bodyName>
      <topicName>base_link_wrench</topicName>
    </plugin>
  </gazebo>
  <gazebo reference="imu_link">
    <!-- this is expected to be reparented to pelvis with appropriate offset
         when imu_link is reduced by fixed joint reduction -->
    <!-- todo: this is working with gazebo 1.4, need to write a unit test -->
    <sensor name="imu_sensor" type="imu">
      <always_on>1</always_on>
      <update_rate>1000.0</update_rate>
      <imu>
        <noise>
          <type>gaussian</type>
          <!-- Noise parameters from Boston Dynamics
               (http://gazebosim.org/wiki/Sensor_noise):
                 rates (rad/s): mean=0, stddev=2e-4
                 accels (m/s/s): mean=0, stddev=1.7e-2
                 rate bias (rad/s): 5e-6 - 1e-5
                 accel bias (m/s/s): 1e-1
               Experimentally, simulation provide rates with noise of
               about 1e-3 rad/s and accels with noise of about 1e-1 m/s/s.
               So we don't expect to see the noise unless number of inner iterations
               are increased.

               We will add bias.  In this model, bias is sampled once for rates
               and once for accels at startup; the sign (negative or positive)
               of each bias is then switched with equal probability.  Thereafter,
               the biases are fixed additive offsets.  We choose
               bias means and stddevs to produce biases close to the provided
               data. -->
          <rate>
            <mean>0.0</mean>
            <stddev>2e-4</stddev>
            <bias_mean>0.0000075</bias_mean>
            <bias_stddev>0.0000008</bias_stddev>
          </rate>
          <accel>
            <mean>0.0</mean>
            <stddev>1.7e-2</stddev>
            <bias_mean>0.1</bias_mean>
            <bias_stddev>0.001</bias_stddev>
          </accel>
        </noise>
      </imu>
    </sensor>
  </gazebo>
  <gazebo reference="r_foot">
    <mu1>0.9</mu1>
    <mu2>0.9</mu2>
    <fdir1>1 0 0</fdir1>
    <maxVel>1.0</maxVel>
    <minDepth>0.003</minDepth>
  </gazebo>
  <gazebo reference="l_foot">
    <mu1>0.9</mu1>
    <mu2>0.9</mu2>
    <fdir1>1 0 0</fdir1>
    <maxVel>1.0</maxVel>
    <minDepth>0.003</minDepth>
  </gazebo>
  <material name="Blue">
    <color rgba="0.0 0.0 0.8 1.0"/>
  </material>
  <material name="Green">
    <color rgba="0.0 0.8 0.0 1.0"/>
  </material>
  <material name="Grey">
    <color rgba="0.7 0.7 0.7 1.0"/>
  </material>
  <material name="LightGrey">
    <color rgba="0.9 0.9 0.9 1.0"/>
  </material>
  <material name="DarkGrey">
    <color rgba="0.2 0.2 0.2 1.0"/>
  </material>
  <material name="Red">
    <color rgba="0.8 0.0 0.0 1.0"/>
  </material>
  <material name="White">
    <color rgba="1.0 1.0 1.0 1.0"/>
  </material>
  <!-- Now we can start using the macros included above to define the actual robot -->
  <!-- The reflect parameter takes the value 1 or -1 to respectively distinguish right from left side in expressions -->
  <link name="leg_right_1_link">
    <inertial>
      <mass value="1.296562"/>
      <origin rpy="0 0 0" xyz="-0.02571 0 0.02557"/>
      <inertia ixx="0.00132187534" ixy="0.00000001514" ixz="0.00040022268" iyy="0.0018528617" iyz="0.00000050713" izz="0.00084231334"/>
    </inertial>
    <visual>
      <origin rpy="0 0 0" xyz="0 0 0"/>
      <geometry>
        <mesh filename="package://reemc_description/meshes/leg/leg_1.dae" scale="1 1 1"/>
      </geometry>
      <material name="LightGrey"/>
    </visual>
  </link>
  <joint name="leg_right_1_joint" type="revolute">
    <origin rpy="0 0 0" xyz="0  -0.075 -0.14353"/>
    <axis xyz="0 0 1"/>
    <parent link="base_link"/>
    <child link="leg_right_1_link"/>
    <dynamics damping="1.0" friction="1.0"/>
    <limit effort="42.7" lower="-0.523598775598" upper="0.785398163397" velocity="2.35"/>
    <safety_controller k_position="100" k_velocity="100" soft_lower_limit="-0.523598775598" soft_upper_limit="0.785398163397"/>
  </joint>
  <link name="leg_right_2_link">
    <inertial>
      <mass value="0.877224"/>
      <origin rpy="0.0 0.0 0.0" xyz="0.00057 -0.00881 -0.01125"/>
      <inertia ixx="0.0008416476" ixy="-0.00000268743" ixz="0.00000667199" iyy="0.00039794844" iyz="0.00002668971" izz="0.00084196694"/>
    </inertial>
    <visual>
      <origin rpy="1.57079632679 0 0" xyz="0 0 0"/>
      <geometry>
        <cylinder length="0.10" radius="0.04"/>
      </geometry>
      <material name="LightGrey"/>
    </visual>
  </link>
  <joint name="leg_right_2_joint" type="revolute">
    <origin rpy="0 1.57079632679 0" xyz="0 0 0.0"/>
    <axis xyz="0 0 1"/>
    <parent link="leg_right_1_link"/>
    <child link="leg_right_2_link"/>
    <dynamics damping="1.0" friction="1.0"/>
    <limit effort="64.0" lower="-0.523598775598" upper="0.261799387799" velocity="2.27"/>
    <safety_controller k_position="100" k_velocity="100" soft_lower_limit="-0.523598775598" soft_upper_limit="0.261799387799"/>
  </joint>
  <link name="leg_right_3_link">
    <inertial>
      <mass value="5.012935"/>
      <origin rpy="0.0 0 0.0" xyz="0.14784 -0.01646 -0.01793"/>
      <inertia ixx="0.00507885174" ixy="-0.00034076421" ixz="-0.00225952731" iyy="0.02850097402" iyz="0.00003047874" izz="0.02632392239"/>
    </inertial>
    <visual>
      <origin rpy="0 0 0" xyz="0 0 0"/>
      <geometry>
        <mesh filename="package://reemc_description/meshes/leg/leg_3.dae" scale="1 1 -1.0"/>
      </geometry>
      <material name="LightGrey"/>
    </visual>
    <collision>
      <origin rpy="0 1.57079632679 0" xyz="0.15 0 -0.015"/>
      <geometry>
        <box size="0.15 0.10 0.20"/>
      </geometry>
    </collision>
  </link>
  <joint name="leg_right_3_joint" type="revolute">
    <origin rpy="-1.57079632679 0 0" xyz="0 0 0.0"/>
    <axis xyz="0 0 1"/>
    <parent link="leg_right_2_link"/>
    <child link="leg_right_3_link"/>
    <dynamics damping="1.0" friction="1.0"/>
    <limit effort="55.7" lower="-1.74532925199" upper="0.785398163397" velocity="3.64"/>
    <safety_controller k_position="100" k_velocity="100" soft_lower_limit="-1.74532925199" soft_upper_limit="0.785398163397"/>
  </joint>
  <link name="leg_right_4_link">
    <inertial>
      <mass value="3.604293"/>
      <origin rpy="0.0 0.0 0.0" xyz="0.14618 -0.0022 -0.02189"/>
      <inertia ixx="0.00361006492" ixy="0.00012218208" ixz="0.00160208242" iyy="0.02470649045" iyz="0.00008129755" izz="0.02272322206"/>
    </inertial>
    <visual>
      <origin rpy="0 0 0" xyz="0 0 0"/>
      <geometry>
        <mesh filename="package://reemc_description/meshes/leg/leg_4.dae" scale="1 1 -1.0"/>
      </geometry>
      <material name="LightGrey"/>
    </visual>
    <collision>
      <origin rpy="0 -1.57079632679 0" xyz="0.15 0 -0.015"/>
      <geometry>
        <box size="0.15 0.10 0.20"/>
      </geometry>
    </collision>
  </link>
  <joint name="leg_right_4_joint" type="revolute">
    <origin rpy="0 0 0" xyz="0.300 0 0.0"/>
    <axis xyz="0 0 1"/>
    <parent link="leg_right_3_link"/>
    <child link="leg_right_4_link"/>
    <dynamics damping="0.1" friction="0"/>
    <dynamics damping="1.0" friction="1.0"/>
    <limit effort="138.3" lower="0.0" upper="2.61799387799" velocity="3.225"/>
    <safety_controller k_position="100" k_velocity="100" soft_lower_limit="0.0" soft_upper_limit="2.61799387799"/>
  </joint>
  <link name="leg_right_5_link">
    <inertial>
      <mass value="0.859484"/>
      <origin rpy="0.0 0.0 0.0" xyz="-0.00028 0.01119 -0.00859"/>
      <inertia ixx="0.00082035023" ixy="0.00000048534" ixz="0.00000226301" iyy="0.00082074105" iyz="-0.00002892247" izz="0.00037614067"/>
    </inertial>
    <visual>
      <origin rpy="0 0 0" xyz="0 0 0"/>
      <geometry>
        <cylinder length="0.104" radius="0.04"/>
      </geometry>
      <material name="LightGrey"/>
    </visual>
  </link>
  <joint name="leg_right_5_joint" type="revolute">
    <origin rpy="0 0 0" xyz="0.30 0 0.0"/>
    <axis xyz="0 0 1"/>
    <parent link="leg_right_4_link"/>
    <child link="leg_right_5_link"/>
    <dynamics damping="1.0" friction="1.0"/>
    <limit effort="80.9" lower="-1.308996939" upper="0.785398163397" velocity="2.44"/>
    <safety_controller k_position="100" k_velocity="100" soft_lower_limit="-1.308996939" soft_upper_limit="0.785398163397"/>
  </joint>
  <link name="leg_right_6_link">
    <inertial>
      <mass value="2.530622"/>
      <origin rpy="0.0 0.0 0.0" xyz="0.06111 -0.00336 -0.00497"/>
      <inertia ixx="0.00366502559" ixy="0.00020479295" ixz="0.00112439297" iyy="0.00532618026" iyz="0.00012133755" izz="0.00353091463"/>
    </inertial>
    <visual>
      <origin rpy="0 0 0" xyz="0 0 0"/>
      <geometry>
        <mesh filename="package://reemc_description/meshes/leg/leg_6.dae" scale="1 -1.0 1"/>
      </geometry>
      <material name="LightGrey"/>
    </visual>
    <collision>
      <origin rpy="0 0 0" xyz="0.1 -0.01 0.025 "/>
      <geometry>
        <box size="0.02 0.14 0.210"/>
      </geometry>
    </collision>
  </link>
  <joint name="leg_right_6_joint" type="revolute">
    <origin rpy="1.57079632679 0 0" xyz="0 0 0"/>
    <axis xyz="0 0 1"/>
    <parent link="leg_right_5_link"/>
    <child link="leg_right_6_link"/>
    <dynamics damping="1.0" friction="1.0"/>
    <limit effort="64.0" lower="-0.261799387799" upper="0.523598775598" velocity="2.27"/>
    <safety_controller k_position="100" k_velocity="100" soft_lower_limit="-0.261799387799" soft_upper_limit="0.523598775598"/>
  </joint>
  <link name="right_sole_link">
    <inertial>
      <mass value="0.001"/>
      <origin rpy="0 0 0" xyz="0 0 0"/>
      <inertia ixx="0.0" ixy="0.0" ixz="0.0" iyy="0.0" iyz="0.0" izz="0.0"/>
    </inertial>
  </link>
  <joint name="right_sole_joint" type="fixed">
    <!-- origin x taken from link_${side}_6_link/visual/origin/x above -->
    <origin rpy="0.0 -1.57079632679 0.0" xyz="0.117 0.0 0.0"/>
    <axis xyz="0 0 1"/>
    <parent link="leg_right_6_link"/>
    <child link="right_sole_link"/>
    <dynamics damping="1.0" friction="1.0"/>
    <limit effort="60" lower="0.0" upper="0.0" velocity="0"/>
  </joint>
  <gazebo reference="leg_right_1_link">
    <mu1>0.9</mu1>
    <mu2>0.9</mu2>
  </gazebo>
  <gazebo reference="leg_right_2_link">
    <mu1>0.9</mu1>
    <mu2>0.9</mu2>
  </gazebo>
  <gazebo reference="leg_right_3_link">
    <mu1>0.9</mu1>
    <mu2>0.9</mu2>
  </gazebo>
  <gazebo reference="leg_right_4_link">
    <mu1>0.9</mu1>
    <mu2>0.9</mu2>
  </gazebo>
  <gazebo reference="leg_right_5_link">
    <mu1>0.9</mu1>
    <mu2>0.9</mu2>
  </gazebo>
  <!-- contact model for foot surface -->
  <gazebo reference="leg_right_6_link">
    <kp>1000000.0</kp>
    <kd>100.0</kd>
    <mu1>1.0</mu1>
    <mu2>1.0</mu2>
    <fdir1>0 0 1</fdir1>
    <maxVel>1.0</maxVel>
    <minDepth>0.00</minDepth>
    <implicitSpringDamper>1</implicitSpringDamper>
  </gazebo>
  <!--force torque sensor -->
  <!--xacro:reemc_force_torque_sensor name="leg_${side}_6_link"  update_rate="100.0"/-->
  <gazebo reference="leg_right_1_joint">
    <implicitSpringDamper>1</implicitSpringDamper>
  </gazebo>
  <gazebo reference="leg_right_2_joint">
    <implicitSpringDamper>1</implicitSpringDamper>
  </gazebo>
  <gazebo reference="leg_right_3_joint">
    <implicitSpringDamper>1</implicitSpringDamper>
  </gazebo>
  <gazebo reference="leg_right_4_joint">
    <implicitSpringDamper>1</implicitSpringDamper>
  </gazebo>
  <gazebo reference="leg_right_5_joint">
    <implicitSpringDamper>1</implicitSpringDamper>
  </gazebo>
  <gazebo reference="leg_right_6_joint">
    <implicitSpringDamper>1</implicitSpringDamper>
    <provideFeedback>1</provideFeedback>
  </gazebo>
  <transmission name="leg_right_1_trans">
    <type>transmission_interface/SimpleTransmission</type>
    <actuator name="leg_right_1_motor">
      <mechanicalReduction>1.0</mechanicalReduction>
    </actuator>
    <joint name="leg_right_1_joint">
      <hardwareInterface>hardware_interface/PositionJointInterface</hardwareInterface>
      <hardwareInterface>hardware_interface/EffortJointInterface</hardwareInterface>
    </joint>
  </transmission>
  <transmission name="leg_right_2_trans">
    <type>transmission_interface/SimpleTransmission</type>
    <actuator name="leg_right_2_motor">
      <mechanicalReduction>1.0</mechanicalReduction>
    </actuator>
    <joint name="leg_right_2_joint">
      <hardwareInterface>hardware_interface/PositionJointInterface</hardwareInterface>
      <hardwareInterface>hardware_interface/EffortJointInterface</hardwareInterface>
    </joint>
  </transmission>
  <transmission name="leg_right_3_trans">
    <type>transmission_interface/SimpleTransmission</type>
    <actuator name="leg_right_3_motor">
      <mechanicalReduction>1.0</mechanicalReduction>
    </actuator>
    <joint name="leg_right_3_joint">
      <hardwareInterface>hardware_interface/PositionJointInterface</hardwareInterface>
      <hardwareInterface>hardware_interface/EffortJointInterface</hardwareInterface>
    </joint>
  </transmission>
  <transmission name="leg_right_4_trans">
    <type>transmission_interface/SimpleTransmission</type>
    <actuator name="leg_right_4_motor">
      <mechanicalReduction>1.0</mechanicalReduction>
    </actuator>
    <joint name="leg_right_4_joint">
      <hardwareInterface>hardware_interface/PositionJointInterface</hardwareInterface>
      <hardwareInterface>hardware_interface/EffortJointInterface</hardwareInterface>
    </joint>
  </transmission>
  <transmission name="leg_right_5_trans">
    <type>transmission_interface/SimpleTransmission</type>
    <actuator name="leg_right_5_motor">
      <mechanicalReduction>1.0</mechanicalReduction>
    </actuator>
    <joint name="leg_right_5_joint">
      <hardwareInterface>hardware_interface/PositionJointInterface</hardwareInterface>
      <hardwareInterface>hardware_interface/EffortJointInterface</hardwareInterface>
    </joint>
  </transmission>
  <transmission name="leg_right_6_trans">
    <type>transmission_interface/SimpleTransmission</type>
    <actuator name="leg_right_6_motor">
      <mechanicalReduction>1.0</mechanicalReduction>
    </actuator>
    <joint name="leg_right_6_joint">
      <hardwareInterface>hardware_interface/PositionJointInterface</hardwareInterface>
      <hardwareInterface>hardware_interface/EffortJointInterface</hardwareInterface>
    </joint>
  </transmission>
  <link name="right_laser_link">
    <inertial>
      <origin rpy="0 0 0" xyz="0.0 0.0 0.0"/>
      <mass value="0.001"/>
      <inertia ixx="3.7174E-05" ixy="4.9927E-08" ixz="1.1015E-05" iyy="4.2412E-05" iyz="-9.8165E-09" izz="4.167E-05"/>
    </inertial>
    <!--    <visual>
         <origin xyz="0.0 0 0.05" rpy="0 0 ${90.0*deg_to_rad}" />
        <geometry>
          <mesh filename="package://reemc_description/meshes/sensors/urg-04lx-ug01.stl" scale="0.001 0.001 0.001"/>
        </geometry>
      <material name="DarkGrey" />
      </visual>
  -->
  </link>
  <joint name="right_laser_joint" type="fixed">
    <axis xyz="0 1 0"/>
    <origin rpy="0.0 0.0 -0.523598775598" xyz="0.085 -0.01 0.073"/>
    <parent link="right_sole_link"/>
    <child link="right_laser_link"/>
    <dynamics damping="1" friction="1.0"/>
    <limit effort="60" lower="0" upper="0" velocity="20"/>
  </joint>
  <gazebo reference="right_laser_link">
    <sensor name="right_laser_sensor" type="ray">
      <pose>0 0 0 0 0 0</pose>
      <visualize>false</visualize>
      <update_rate>10.0</update_rate>
      <ray>
        <scan>
          <horizontal>
            <samples>360</samples>
            <resolution>1</resolution>
            <min_angle>-1.57079632679</min_angle>
            <max_angle>1.57079632679</max_angle>
          </horizontal>
        </scan>
        <range>
          <min>0.02</min>
          <max>5.6</max>
          <resolution>0.01</resolution>
        </range>
      </ray>
      <plugin filename="libgazebo_ros_laser.so" name="gazebo_ros_laser">
        <frameName>/right_laser_link</frameName>
        <topicName>right_scan</topicName>
        <gaussianNoise>0.03</gaussianNoise>
        <hokuyoMinIntensity>101</hokuyoMinIntensity>
        <updateRate>10.0</updateRate>
        <alwaysOn>true</alwaysOn>
      </plugin>
    </sensor>
  </gazebo>
  <link name="leg_left_1_link">
    <inertial>
      <mass value="1.296562"/>
      <origin rpy="0 0 0" xyz="-0.02571 0 0.02557"/>
      <inertia ixx="0.00132187534" ixy="0.00000001514" ixz="0.00040022268" iyy="0.0018528617" iyz="0.00000050713" izz="0.00084231334"/>
    </inertial>
    <visual>
      <origin rpy="0 0 0" xyz="0 0 0"/>
      <geometry>
        <mesh filename="package://reemc_description/meshes/leg/leg_1.dae" scale="1 1 1"/>
      </geometry>
      <material name="LightGrey"/>
    </visual>
  </link>
  <joint name="leg_left_1_joint" type="revolute">
    <origin rpy="0 0 0" xyz="0  0.075 -0.14353"/>
    <axis xyz="0 0 1"/>
    <parent link="base_link"/>
    <child link="leg_left_1_link"/>
    <dynamics damping="1.0" friction="1.0"/>
    <limit effort="42.7" lower="-0.785398163397" upper="0.523598775598" velocity="2.35"/>
    <safety_controller k_position="100" k_velocity="100" soft_lower_limit="-0.785398163397" soft_upper_limit="0.523598775598"/>
  </joint>
  <link name="leg_left_2_link">
    <inertial>
      <mass value="0.877224"/>
      <origin rpy="0.0 0.0 0.0" xyz="0.00057 0.00881 -0.01125"/>
      <inertia ixx="0.0008416476" ixy="-0.00000268743" ixz="0.00000667199" iyy="0.00039794844" iyz="0.00002668971" izz="0.00084196694"/>
    </inertial>
    <visual>
      <origin rpy="1.57079632679 0 0" xyz="0 0 0"/>
      <geometry>
        <cylinder length="0.10" radius="0.04"/>
      </geometry>
      <material name="LightGrey"/>
    </visual>
  </link>
  <joint name="leg_left_2_joint" type="revolute">
    <origin rpy="0 1.57079632679 0" xyz="0 0 0.0"/>
    <axis xyz="0 0 1"/>
    <parent link="leg_left_1_link"/>
    <child link="leg_left_2_link"/>
    <dynamics damping="1.0" friction="1.0"/>
    <limit effort="64.0" lower="-0.261799387799" upper="0.523598775598" velocity="2.27"/>
    <safety_controller k_position="100" k_velocity="100" soft_lower_limit="-0.261799387799" soft_upper_limit="0.523598775598"/>
  </joint>
  <link name="leg_left_3_link">
    <inertial>
      <mass value="5.012935"/>
      <origin rpy="0.0 0 0.0" xyz="0.14784 -0.01646 0.01793"/>
      <inertia ixx="0.00507885174" ixy="-0.00034076421" ixz="-0.00225952731" iyy="0.02850097402" iyz="0.00003047874" izz="0.02632392239"/>
    </inertial>
    <visual>
      <origin rpy="0 0 0" xyz="0 0 0"/>
      <geometry>
        <mesh filename="package://reemc_description/meshes/leg/leg_3.dae" scale="1 1 1.0"/>
      </geometry>
      <material name="LightGrey"/>
    </visual>
    <collision>
      <origin rpy="0 1.57079632679 0" xyz="0.15 0 0.015"/>
      <geometry>
        <box size="0.15 0.10 0.20"/>
      </geometry>
    </collision>
  </link>
  <joint name="leg_left_3_joint" type="revolute">
    <origin rpy="-1.57079632679 0 0" xyz="0 0 0.0"/>
    <axis xyz="0 0 1"/>
    <parent link="leg_left_2_link"/>
    <child link="leg_left_3_link"/>
    <dynamics damping="1.0" friction="1.0"/>
    <limit effort="55.7" lower="-1.74532925199" upper="0.785398163397" velocity="3.64"/>
    <safety_controller k_position="100" k_velocity="100" soft_lower_limit="-1.74532925199" soft_upper_limit="0.785398163397"/>
  </joint>
  <link name="leg_left_4_link">
    <inertial>
      <mass value="3.604293"/>
      <origin rpy="0.0 0.0 0.0" xyz="0.14618 -0.0022 0.02189"/>
      <inertia ixx="0.00361006492" ixy="0.00012218208" ixz="0.00160208242" iyy="0.02470649045" iyz="0.00008129755" izz="0.02272322206"/>
    </inertial>
    <visual>
      <origin rpy="0 0 0" xyz="0 0 0"/>
      <geometry>
        <mesh filename="package://reemc_description/meshes/leg/leg_4.dae" scale="1 1 1.0"/>
      </geometry>
      <material name="LightGrey"/>
    </visual>
    <collision>
      <origin rpy="0 1.57079632679 0" xyz="0.15 0 0.015"/>
      <geometry>
        <box size="0.15 0.10 0.20"/>
      </geometry>
    </collision>
  </link>
  <joint name="leg_left_4_joint" type="revolute">
    <origin rpy="0 0 0" xyz="0.300 0 0.0"/>
    <axis xyz="0 0 1"/>
    <parent link="leg_left_3_link"/>
    <child link="leg_left_4_link"/>
    <dynamics damping="0.1" friction="0"/>
    <dynamics damping="1.0" friction="1.0"/>
    <limit effort="138.3" lower="0.0" upper="2.61799387799" velocity="3.225"/>
    <safety_controller k_position="100" k_velocity="100" soft_lower_limit="0.0" soft_upper_limit="2.61799387799"/>
  </joint>
  <link name="leg_left_5_link">
    <inertial>
      <mass value="0.859484"/>
      <origin rpy="0.0 0.0 0.0" xyz="-0.00028 0.01119 0.00859"/>
      <inertia ixx="0.00082035023" ixy="0.00000048534" ixz="0.00000226301" iyy="0.00082074105" iyz="-0.00002892247" izz="0.00037614067"/>
    </inertial>
    <visual>
      <origin rpy="0 0 0" xyz="0 0 0"/>
      <geometry>
        <cylinder length="0.104" radius="0.04"/>
      </geometry>
      <material name="LightGrey"/>
    </visual>
  </link>
  <joint name="leg_left_5_joint" type="revolute">
    <origin rpy="0 0 0" xyz="0.30 0 0.0"/>
    <axis xyz="0 0 1"/>
    <parent link="leg_left_4_link"/>
    <child link="leg_left_5_link"/>
    <dynamics damping="1.0" friction="1.0"/>
    <limit effort="80.9" lower="-1.308996939" upper="0.785398163397" velocity="2.44"/>
    <safety_controller k_position="100" k_velocity="100" soft_lower_limit="-1.308996939" soft_upper_limit="0.785398163397"/>
  </joint>
  <link name="leg_left_6_link">
    <inertial>
      <mass value="2.530622"/>
      <origin rpy="0.0 0.0 0.0" xyz="0.06111 0.00336 -0.00497"/>
      <inertia ixx="0.00366502559" ixy="0.00020479295" ixz="0.00112439297" iyy="0.00532618026" iyz="0.00012133755" izz="0.00353091463"/>
    </inertial>
    <visual>
      <origin rpy="0 0 0" xyz="0 0 0"/>
      <geometry>
        <mesh filename="package://reemc_description/meshes/leg/leg_6.dae" scale="1 1.0 1"/>
      </geometry>
      <material name="LightGrey"/>
    </visual>
    <collision>
      <origin rpy="0 0 0" xyz="0.1 0.01 0.025 "/>
      <geometry>
        <box size="0.02 0.14 0.210"/>
      </geometry>
    </collision>
  </link>
  <joint name="leg_left_6_joint" type="revolute">
    <origin rpy="1.57079632679 0 0" xyz="0 0 0"/>
    <axis xyz="0 0 1"/>
    <parent link="leg_left_5_link"/>
    <child link="leg_left_6_link"/>
    <dynamics damping="1.0" friction="1.0"/>
    <limit effort="64.0" lower="-0.523598775598" upper="0.261799387799" velocity="2.27"/>
    <safety_controller k_position="100" k_velocity="100" soft_lower_limit="-0.523598775598" soft_upper_limit="0.261799387799"/>
  </joint>
  <link name="left_sole_link">
    <inertial>
      <mass value="0.001"/>
      <origin rpy="0 0 0" xyz="0 0 0"/>
      <inertia ixx="0.0" ixy="0.0" ixz="0.0" iyy="0.0" iyz="0.0" izz="0.0"/>
    </inertial>
  </link>
  <joint name="left_sole_joint" type="fixed">
    <!-- origin x taken from link_${side}_6_link/visual/origin/x above -->
    <origin rpy="0.0 -1.57079632679 0.0" xyz="0.117 0.0 0.0"/>
    <axis xyz="0 0 1"/>
    <parent link="leg_left_6_link"/>
    <child link="left_sole_link"/>
    <dynamics damping="1.0" friction="1.0"/>
    <limit effort="60" lower="0.0" upper="0.0" velocity="0"/>
  </joint>
  <gazebo reference="leg_left_1_link">
    <mu1>0.9</mu1>
    <mu2>0.9</mu2>
  </gazebo>
  <gazebo reference="leg_left_2_link">
    <mu1>0.9</mu1>
    <mu2>0.9</mu2>
  </gazebo>
  <gazebo reference="leg_left_3_link">
    <mu1>0.9</mu1>
    <mu2>0.9</mu2>
  </gazebo>
  <gazebo reference="leg_left_4_link">
    <mu1>0.9</mu1>
    <mu2>0.9</mu2>
  </gazebo>
  <gazebo reference="leg_left_5_link">
    <mu1>0.9</mu1>
    <mu2>0.9</mu2>
  </gazebo>
  <!-- contact model for foot surface -->
  <gazebo reference="leg_left_6_link">
    <kp>1000000.0</kp>
    <kd>100.0</kd>
    <mu1>1.0</mu1>
    <mu2>1.0</mu2>
    <fdir1>0 0 1</fdir1>
    <maxVel>1.0</maxVel>
    <minDepth>0.00</minDepth>
    <implicitSpringDamper>1</implicitSpringDamper>
  </gazebo>
  <!--force torque sensor -->
  <!--xacro:reemc_force_torque_sensor name="leg_${side}_6_link"  update_rate="100.0"/-->
  <gazebo reference="leg_left_1_joint">
    <implicitSpringDamper>1</implicitSpringDamper>
  </gazebo>
  <gazebo reference="leg_left_2_joint">
    <implicitSpringDamper>1</implicitSpringDamper>
  </gazebo>
  <gazebo reference="leg_left_3_joint">
    <implicitSpringDamper>1</implicitSpringDamper>
  </gazebo>
  <gazebo reference="leg_left_4_joint">
    <implicitSpringDamper>1</implicitSpringDamper>
  </gazebo>
  <gazebo reference="leg_left_5_joint">
    <implicitSpringDamper>1</implicitSpringDamper>
  </gazebo>
  <gazebo reference="leg_left_6_joint">
    <implicitSpringDamper>1</implicitSpringDamper>
    <provideFeedback>1</provideFeedback>
  </gazebo>
  <transmission name="leg_left_1_trans">
    <type>transmission_interface/SimpleTransmission</type>
    <actuator name="leg_left_1_motor">
      <mechanicalReduction>1.0</mechanicalReduction>
    </actuator>
    <joint name="leg_left_1_joint">
      <hardwareInterface>hardware_interface/PositionJointInterface</hardwareInterface>
      <hardwareInterface>hardware_interface/EffortJointInterface</hardwareInterface>
    </joint>
  </transmission>
  <transmission name="leg_left_2_trans">
    <type>transmission_interface/SimpleTransmission</type>
    <actuator name="leg_left_2_motor">
      <mechanicalReduction>1.0</mechanicalReduction>
    </actuator>
    <joint name="leg_left_2_joint">
      <hardwareInterface>hardware_interface/PositionJointInterface</hardwareInterface>
      <hardwareInterface>hardware_interface/EffortJointInterface</hardwareInterface>
    </joint>
  </transmission>
  <transmission name="leg_left_3_trans">
    <type>transmission_interface/SimpleTransmission</type>
    <actuator name="leg_left_3_motor">
      <mechanicalReduction>1.0</mechanicalReduction>
    </actuator>
    <joint name="leg_left_3_joint">
      <hardwareInterface>hardware_interface/PositionJointInterface</hardwareInterface>
      <hardwareInterface>hardware_interface/EffortJointInterface</hardwareInterface>
    </joint>
  </transmission>
  <transmission name="leg_left_4_trans">
    <type>transmission_interface/SimpleTransmission</type>
    <actuator name="leg_left_4_motor">
      <mechanicalReduction>1.0</mechanicalReduction>
    </actuator>
    <joint name="leg_left_4_joint">
      <hardwareInterface>hardware_interface/PositionJointInterface</hardwareInterface>
      <hardwareInterface>hardware_interface/EffortJointInterface</hardwareInterface>
    </joint>
  </transmission>
  <transmission name="leg_left_5_trans">
    <type>transmission_interface/SimpleTransmission</type>
    <actuator name="leg_left_5_motor">
      <mechanicalReduction>1.0</mechanicalReduction>
    </actuator>
    <joint name="leg_left_5_joint">
      <hardwareInterface>hardware_interface/PositionJointInterface</hardwareInterface>
      <hardwareInterface>hardware_interface/EffortJointInterface</hardwareInterface>
    </joint>
  </transmission>
  <transmission name="leg_left_6_trans">
    <type>transmission_interface/SimpleTransmission</type>
    <actuator name="leg_left_6_motor">
      <mechanicalReduction>1.0</mechanicalReduction>
    </actuator>
    <joint name="leg_left_6_joint">
      <hardwareInterface>hardware_interface/PositionJointInterface</hardwareInterface>
      <hardwareInterface>hardware_interface/EffortJointInterface</hardwareInterface>
    </joint>
  </transmission>
  <link name="left_laser_link">
    <inertial>
      <origin rpy="0 0 0" xyz="0.0 0.0 0.0"/>
      <mass value="0.001"/>
      <inertia ixx="3.7174E-05" ixy="4.9927E-08" ixz="1.1015E-05" iyy="4.2412E-05" iyz="-9.8165E-09" izz="4.167E-05"/>
    </inertial>
    <!--    <visual>
         <origin xyz="0.0 0 0.05" rpy="0 0 ${90.0*deg_to_rad}" />
        <geometry>
          <mesh filename="package://reemc_description/meshes/sensors/urg-04lx-ug01.stl" scale="0.001 0.001 0.001"/>
        </geometry>
      <material name="DarkGrey" />
      </visual>
  -->
  </link>
  <joint name="left_laser_joint" type="fixed">
    <axis xyz="0 1 0"/>
    <origin rpy="0.0 0.0 0.523598775598" xyz="0.085 0.01 0.073"/>
    <parent link="left_sole_link"/>
    <child link="left_laser_link"/>
    <dynamics damping="1" friction="1.0"/>
    <limit effort="60" lower="0" upper="0" velocity="20"/>
  </joint>
  <gazebo reference="left_laser_link">
    <sensor name="left_laser_sensor" type="ray">
      <pose>0 0 0 0 0 0</pose>
      <visualize>false</visualize>
      <update_rate>10.0</update_rate>
      <ray>
        <scan>
          <horizontal>
            <samples>360</samples>
            <resolution>1</resolution>
            <min_angle>-1.57079632679</min_angle>
            <max_angle>1.57079632679</max_angle>
          </horizontal>
        </scan>
        <range>
          <min>0.02</min>
          <max>5.6</max>
          <resolution>0.01</resolution>
        </range>
      </ray>
      <plugin filename="libgazebo_ros_laser.so" name="gazebo_ros_laser">
        <frameName>/left_laser_link</frameName>
        <topicName>left_scan</topicName>
        <gaussianNoise>0.03</gaussianNoise>
        <hokuyoMinIntensity>101</hokuyoMinIntensity>
        <updateRate>10.0</updateRate>
        <alwaysOn>true</alwaysOn>
      </plugin>
    </sensor>
  </gazebo>
  <!--************************-->
  <!--        TORSO_1         -->
  <!--************************-->
  <link name="torso_1_link">
    <inertial>
      <origin rpy="0 0 0" xyz="-0.00011 -0.00002 -0.00669"/>
      <mass value="1.995096"/>
      <!-- NOTE: Assuming cylinder with length="0.295" radius="0.0465-->
      <inertia ixx="0.0036591855" ixy="0.00000036753" ixz="0.00000297759" iyy="0.00115955355" iyz="0.00000024742" izz="0.00360440105"/>
    </inertial>
    <visual>
      <origin rpy="1.57079632679 0 0" xyz="0 0 0"/>
      <geometry>
        <cylinder length="0.15" radius="0.0465"/>
      </geometry>
      <material name="DarkGrey"/>
    </visual>
  </link>
  <joint name="torso_1_joint" type="revolute">
    <parent link="base_link"/>
    <child link="torso_1_link"/>
    <origin rpy="0 0 0" xyz="0 0 0.14353"/>
    <axis xyz="0 0 1"/>
    <limit effort="78.0" lower="-1.308996939" upper="1.308996939" velocity="5.4"/>
    <dynamics damping="1.0" friction="1.0"/>
    <safety_controller k_position="20" k_velocity="20" soft_lower_limit="-1.288996939" soft_upper_limit="1.288996939"/>
  </joint>
  <!--************************-->
  <!--        TORSO_2         -->
  <!--************************-->
  <link name="torso_2_link">
    <inertial>
      <origin rpy="0 0 0" xyz="-0.01816 -0.17956 -0.00103"/>
      <mass value="14.088098"/>
      <!-- NOTE: Assuming box with d=0.2, w=0.295, h=0.254 -->
      <inertia ixx="0.159836691" ixy="-0.00377573015" ixz="0.00094280162" iyy="0.08484637595" iyz="0.00020220508" izz="0.13253975464"/>
    </inertial>
    <visual>
      <origin rpy="0 0 0" xyz="0 0 0"/>
      <geometry>
        <mesh filename="package://reemc_description/meshes/torso/torso_2.dae"/>
      </geometry>
      <material name="LightGrey"/>
    </visual>
    <collision>
      <origin rpy="0 0 0" xyz="0 0 0"/>
      <geometry>
        <mesh filename="package://reemc_description/meshes/torso/torso_2_collision.stl"/>
      </geometry>
    </collision>
  </link>
  <joint name="torso_2_joint" type="revolute">
    <parent link="torso_1_link"/>
    <child link="torso_2_link"/>
    <origin rpy="-1.57079632679 0 0" xyz="0 0 0"/>
    <axis xyz="0 0 1"/>
    <limit effort="78.0" lower="-0.261799387799" upper="0.785398163397" velocity="5.4"/>
    <dynamics damping="1.0" friction="1.0"/>
    <safety_controller k_position="20" k_velocity="20" soft_lower_limit="-0.241799387799" soft_upper_limit="0.765398163397"/>
  </joint>
  <gazebo reference="torso_1_link">
    <mu1>0.9</mu1>
    <mu2>0.9</mu2>
  </gazebo>
  <gazebo reference="torso_2_link">
    <mu1>0.9</mu1>
    <mu2>0.9</mu2>
  </gazebo>
  <gazebo reference="torso_1_joint">
    <implicitSpringDamper>1</implicitSpringDamper>
  </gazebo>
  <gazebo reference="torso_2_joint">
    <implicitSpringDamper>1</implicitSpringDamper>
    <provideFeedback>1</provideFeedback>
  </gazebo>
  <link name="torso_sonar_01_link">
    <inertial>
      <mass value="0.001"/>
      <origin rpy="0 0 0" xyz="0 0 0"/>
      <inertia ixx="0.0001" ixy="0" ixz="0" iyy="0.000001" iyz="0" izz="0.0001"/>
    </inertial>
  </link>
  <joint name="torso_sonar_01_joint" type="fixed">
    <origin rpy="0.0 0.0 0.349065850399" xyz="0.10 -0.029 0"/>
    <axis xyz="0 0 1"/>
    <parent link="torso_2_link"/>
    <child link="torso_sonar_01_link"/>
  </joint>
  <gazebo reference="torso_sonar_01_link">
    <sensor name="torso_sonar_01" type="ray">
      <pose>0 0 0 0 0 0</pose>
      <update_rate>5</update_rate>
      <visualize>false</visualize>
      <ray>
        <scan>
          <horizontal>
            <samples>5</samples>
            <resolution>1</resolution>
            <min_angle>-0.17455</min_angle>
            <max_angle>0.17455</max_angle>
          </horizontal>
          <vertical>
            <samples>5</samples>
            <resolution>1</resolution>
            <min_angle>-0.17455</min_angle>
            <max_angle>0.17455</max_angle>
          </vertical>
        </scan>
        <range>
          <min>0.005</min>
          <max>0.7</max>
          <resolution>0.01</resolution>
        </range>
      </ray>
      <plugin filename="libgazebo_ros_range.so" name="gazebo_ros_range">
        <gaussianNoise>0.005</gaussianNoise>
        <alwaysOn>true</alwaysOn>
        <updateRate>5</updateRate>
        <topicName>sonar_torso</topicName>
        <frameName>torso_sonar_01_link</frameName>
        <minRange>0.005</minRange>
        <maxRange>0.7</maxRange>
        <fov>0.3491</fov>
        <radiation>ultrasound</radiation>
      </plugin>
    </sensor>
  </gazebo>
  <link name="torso_sonar_02_link">
    <inertial>
      <mass value="0.001"/>
      <origin rpy="0 0 0" xyz="0 0 0"/>
      <inertia ixx="0.0001" ixy="0" ixz="0" iyy="0.000001" iyz="0" izz="0.0001"/>
    </inertial>
  </link>
  <joint name="torso_sonar_02_joint" type="fixed">
    <origin rpy="0.0 0.0 0.0" xyz="0.15 -0.18 0"/>
    <axis xyz="0 0 1"/>
    <parent link="torso_2_link"/>
    <child link="torso_sonar_02_link"/>
  </joint>
  <gazebo reference="torso_sonar_02_link">
    <sensor name="torso_sonar_02" type="ray">
      <pose>0 0 0 0 0 0</pose>
      <update_rate>5</update_rate>
      <visualize>false</visualize>
      <ray>
        <scan>
          <horizontal>
            <samples>5</samples>
            <resolution>1</resolution>
            <min_angle>-0.17455</min_angle>
            <max_angle>0.17455</max_angle>
          </horizontal>
          <vertical>
            <samples>5</samples>
            <resolution>1</resolution>
            <min_angle>-0.17455</min_angle>
            <max_angle>0.17455</max_angle>
          </vertical>
        </scan>
        <range>
          <min>0.005</min>
          <max>0.7</max>
          <resolution>0.01</resolution>
        </range>
      </ray>
      <plugin filename="libgazebo_ros_range.so" name="gazebo_ros_range">
        <gaussianNoise>0.005</gaussianNoise>
        <alwaysOn>true</alwaysOn>
        <updateRate>5</updateRate>
        <topicName>sonar_torso</topicName>
        <frameName>torso_sonar_02_link</frameName>
        <minRange>0.005</minRange>
        <maxRange>0.7</maxRange>
        <fov>0.3491</fov>
        <radiation>ultrasound</radiation>
      </plugin>
    </sensor>
  </gazebo>
  <link name="torso_sonar_04_link">
    <inertial>
      <mass value="0.001"/>
      <origin rpy="0 0 0" xyz="0 0 0"/>
      <inertia ixx="0.0001" ixy="0" ixz="0" iyy="0.000001" iyz="0" izz="0.0001"/>
    </inertial>
  </link>
  <joint name="torso_sonar_04_joint" type="fixed">
    <origin rpy="0.0 3.14159265359 0.0" xyz="-0.17 -0.029 0.0"/>
    <axis xyz="0 0 1"/>
    <parent link="torso_2_link"/>
    <child link="torso_sonar_04_link"/>
  </joint>
  <gazebo reference="torso_sonar_04_link">
    <sensor name="torso_sonar_04" type="ray">
      <pose>0 0 0 0 0 0</pose>
      <update_rate>5</update_rate>
      <visualize>false</visualize>
      <ray>
        <scan>
          <horizontal>
            <samples>5</samples>
            <resolution>1</resolution>
            <min_angle>-0.17455</min_angle>
            <max_angle>0.17455</max_angle>
          </horizontal>
          <vertical>
            <samples>5</samples>
            <resolution>1</resolution>
            <min_angle>-0.17455</min_angle>
            <max_angle>0.17455</max_angle>
          </vertical>
        </scan>
        <range>
          <min>0.005</min>
          <max>0.7</max>
          <resolution>0.01</resolution>
        </range>
      </ray>
      <plugin filename="libgazebo_ros_range.so" name="gazebo_ros_range">
        <gaussianNoise>0.005</gaussianNoise>
        <alwaysOn>true</alwaysOn>
        <updateRate>5</updateRate>
        <topicName>sonar_torso</topicName>
        <frameName>torso_sonar_04_link</frameName>
        <minRange>0.005</minRange>
        <maxRange>0.7</maxRange>
        <fov>0.3491</fov>
        <radiation>ultrasound</radiation>
      </plugin>
    </sensor>
  </gazebo>
  <transmission name="torso_trans">
    <type>transmission_interface/DifferentialTransmission</type>
    <actuator name="torso_1_motor">
      <role>actuator1</role>
      <mechanicalReduction>1.0</mechanicalReduction>
    </actuator>
    <actuator name="torso_2_motor">
      <role>actuator2</role>
      <mechanicalReduction>1.0</mechanicalReduction>
    </actuator>
    <joint name="torso_1_joint">
      <role>joint1</role>
      <offset>0.0</offset>
      <mechanicalReduction>1.0</mechanicalReduction>
      <hardwareInterface>hardware_interface/PositionJointInterface</hardwareInterface>
      <hardwareInterface>hardware_interface/EffortJointInterface</hardwareInterface>
    </joint>
    <joint name="torso_2_joint">
      <role>joint2</role>
      <offset>0.0</offset>
      <mechanicalReduction>1.0</mechanicalReduction>
      <hardwareInterface>hardware_interface/PositionJointInterface</hardwareInterface>
      <hardwareInterface>hardware_interface/EffortJointInterface</hardwareInterface>
    </joint>
  </transmission>
  <link name="head_1_link">
    <inertial>
      <origin rpy="0 0 0" xyz="0.01819 0.00248 -0.00517"/>
      <mass value="1.410784"/>
      <!-- NOTE: Assuming cylinder with r=0.06, h=0.08 -->
      <!--         <inertia ixx="0.0014125"  ixy="0"  ixz="0" iyy="0.0014125" iyz="0" izz="0.0017738" /> -->
      <inertia ixx="0.00111370229" ixy="0.00003992198" ixz="-0.00012464155" iyy="0.00111361487" iyz="0.00001943162" izz="0.00114794061"/>
    </inertial>
    <visual>
      <origin rpy="0 0 0" xyz="-0.03 0 0"/>
      <!--TODO: Remove offset when good meshes arrive-->
      <geometry>
        <mesh filename="package://reemc_description/meshes/head/head_1.dae"/>
      </geometry>
      <material name="DarkGrey"/>
    </visual>
    <collision>
      <origin rpy="0 0 0" xyz="-0.03 0 0"/>
      <geometry>
        <mesh filename="package://reemc_description/meshes/head/head_1_collision.stl"/>
      </geometry>
    </collision>
  </link>
  <joint name="head_1_joint" type="revolute">
    <parent link="torso_2_link"/>
    <child link="head_1_link"/>
    <origin rpy="1.57079632679 0 0" xyz="0.0 -0.42316 0"/>
    <axis xyz="0 0 1"/>
    <limit effort="3.4" lower="-1.308996939" upper="1.308996939" velocity="3.0"/>
    <dynamics damping="0.5" friction="1.0"/>
    <safety_controller k_position="20" k_velocity="20" soft_lower_limit="-1.288996939" soft_upper_limit="1.288996939"/>
  </joint>
  <gazebo reference="head_1_link">
    <mu1>0.9</mu1>
    <mu2>0.9</mu2>
  </gazebo>
  <gazebo reference="head_1_joint">
    <implicitSpringDamper>1</implicitSpringDamper>
  </gazebo>
  <link name="head_2_link">
    <inertial>
      <origin rpy="0 0 0" xyz="0.01183 -0.08098 0.00104"/>
      <mass value="2.055488"/>
      <!-- NOTE: Assuming box with d=0.28433, w=0.20302, h=0.26741 -->
      <!--         <inertia ixx="0.011353"  ixy="0"  ixz="0" iyy="0.012294" iyz="0" izz="0.015345" /> -->
      <!--NOTE: Low (0.1 or lower) diagonal inertia values make Gazebo 1.0.2 simulation unstable when head sensors are added.-->
      <inertia ixx="0.00640199093" ixy="0.00012197067" ixz="-0.00000897011" iyy="0.00676228591" iyz="-0.0000552329" izz="0.00614192438"/>
    </inertial>
    <visual>
      <origin rpy="0 0 0" xyz="-0.03 0 0"/>
      <!--TODO: Remove offset when good meshes arrive-->
      <geometry>
        <mesh filename="package://reemc_description/meshes/head/head_2.dae"/>
      </geometry>
      <material name="LightGrey"/>
    </visual>
    <collision>
      <origin rpy="0 0 0" xyz="-0.03 0 0"/>
      <geometry>
        <mesh filename="package://reemc_description/meshes/head/head_2_collision.stl"/>
      </geometry>
    </collision>
  </link>
  <joint name="head_2_joint" type="revolute">
    <parent link="head_1_link"/>
    <child link="head_2_link"/>
    <origin rpy="-1.57079632679 0 0" xyz="0.0445 0 0"/>
    <axis xyz="0 0 1"/>
    <limit effort="3.26" lower="-0.261799387799" upper="0.785398163397" velocity="3.0"/>
    <dynamics damping="0.5" friction="1.0"/>
    <safety_controller k_position="20" k_velocity="20" soft_lower_limit="-0.241799387799" soft_upper_limit="0.785398163397"/>
  </joint>
  <gazebo reference="head_2_link">
    <mu1>0.9</mu1>
    <mu2>0.9</mu2>
  </gazebo>
  <gazebo reference="head_2_joint">
    <implicitSpringDamper>1</implicitSpringDamper>
  </gazebo>
  <link name="head_sonar_03_link">
    <inertial>
      <mass value="0.001"/>
      <origin rpy="0 0 0" xyz="0 0 0"/>
      <inertia ixx="0.0001" ixy="0" ixz="0" iyy="0.000001" iyz="0" izz="0.0001"/>
    </inertial>
  </link>
  <joint name="head_sonar_03_joint" type="fixed">
    <origin rpy="1.57 0.0 0.0" xyz="0.11 -0.195 0.0"/>
    <axis xyz="0 0 1"/>
    <parent link="head_2_link"/>
    <child link="head_sonar_03_link"/>
  </joint>
  <gazebo reference="head_sonar_03_link">
    <sensor name="head_sonar_03" type="ray">
      <pose>0 0 0 0 0 0</pose>
      <update_rate>5</update_rate>
      <visualize>false</visualize>
      <ray>
        <scan>
          <horizontal>
            <samples>5</samples>
            <resolution>1</resolution>
            <min_angle>-0.17455</min_angle>
            <max_angle>0.17455</max_angle>
          </horizontal>
          <vertical>
            <samples>5</samples>
            <resolution>1</resolution>
            <min_angle>-0.17455</min_angle>
            <max_angle>0.17455</max_angle>
          </vertical>
        </scan>
        <range>
          <min>0.0</min>
          <max>0.6</max>
          <resolution>0.01</resolution>
        </range>
      </ray>
      <plugin filename="libgazebo_ros_range.so" name="gazebo_ros_range">
        <gaussianNoise>0.005</gaussianNoise>
        <alwaysOn>true</alwaysOn>
        <updateRate>5</updateRate>
        <topicName>sonar_torso</topicName>
        <frameName>head_sonar_03_link</frameName>
        <minRange>0.0</minRange>
        <maxRange>0.6</maxRange>
        <fov>0.3491</fov>
        <radiation>ultrasound</radiation>
      </plugin>
    </sensor>
  </gazebo>
  <transmission name="head">
    <type>pal_transmissions/HeadTransmission</type>
    <actuator name="head_1_motor">
      <role>independent</role>
      <mechanicalReduction>1.0</mechanicalReduction>
    </actuator>
    <actuator name="head_2_motor">
      <role>dependent</role>
      <mechanicalReduction>1.0</mechanicalReduction>
    </actuator>
    <joint name="head_1_joint">
      <role>independent</role>
      <hardwareInterface>hardware_interface/PositionJointInterface</hardwareInterface>
    </joint>
    <joint name="head_2_joint">
      <role>dependent</role>
      <limits>
        <key> -0.872664625997 </key>
        <max> 0.244346095279 </max>
      </limits>
      <limits>
        <key> -0.698131700798 </key>
        <max> 0.314159265359 </max>
      </limits>
      <limits>
        <key> -0.523598775598 </key>
        <max> 0.471238898038 </max>
      </limits>
      <limits>
        <key> -0.349065850399 </key>
        <max> 0.680678408278 </max>
      </limits>
      <limits>
        <key> -0.174532925199 </key>
        <max> 0.785398163397 </max>
      </limits>
      <limits>
        <key> 0.174532925199 </key>
        <max> 0.785398163397 </max>
      </limits>
      <limits>
        <key> 0.349065850399 </key>
        <max> 0.680678408278 </max>
      </limits>
      <limits>
        <key> 0.523598775598 </key>
        <max> 0.471238898038 </max>
      </limits>
      <limits>
        <key> 0.698131700798 </key>
        <max> 0.314159265359 </max>
      </limits>
      <limits>
        <key> 0.872664625997 </key>
        <max> 0.244346095279 </max>
      </limits>
      <hardwareInterface>hardware_interface/PositionJointInterface</hardwareInterface>
    </joint>
  </transmission>
  <!--************************-->
  <!--        SHOULDER        -->
  <!--************************-->
  <link name="arm_right_1_link">
    <inertial>
      <origin rpy="0 0 0" xyz="0.00701 -0.00011 0.18627"/>
      <mass value="1.935536"/>
      <!--        <inertia ixx="0"  ixy="0"  ixz="0" iyy="0" iyz="0" izz="0" /> -->
      <!--         NOTE: Assuming cylinder centered at CoM with r=0.05, h=0.05 with axis parallel to x coordinate -->
      <!--        <inertia ixx="0.0026850"  ixy="0"  ixz="0" iyy="0.0017900" iyz="0" izz="0.0017900" /> -->
      <inertia ixx="0.00327313329" ixy="-0.00000460054" ixz="-0.00025121368" iyy="0.00316047802" iyz="0.00000313158" izz="0.00157642528"/>
    </inertial>
    <visual>
      <origin rpy="0 0 0" xyz="0 0 0"/>
      <geometry>
        <mesh filename="package://reemc_description/meshes/arm/arm_1.dae" scale="1 1 -1.0"/>
      </geometry>
      <material name="DarkGrey"/>
    </visual>
    <collision>
      <origin rpy="0 0 0" xyz="0 0 0"/>
      <geometry>
        <mesh filename="package://reemc_description/meshes/arm/arm_1_collision.stl" scale="1 1 -1.0"/>
      </geometry>
    </collision>
  </link>
  <joint name="arm_right_1_joint" type="revolute">
    <parent link="torso_2_link"/>
    <child link="arm_right_1_link"/>
    <origin rpy="-2.87979326579 0 0" xyz="0 -0.31827 0"/>
    <axis xyz="0 0 1"/>
    <limit effort="44.64" lower="-0.785398163397" upper="3.14159265359" velocity="2.7"/>
    <dynamics damping="1.0" friction="1.0"/>
    <safety_controller k_position="20" k_velocity="20" soft_lower_limit="-0.765398163397" soft_upper_limit="3.12159265359"/>
  </joint>
  <link name="arm_right_2_link">
    <inertial>
      <origin rpy="0 0 0" xyz="0.01435 -0.06294 0.01039"/>
      <mass value="2.020952"/>
      <!--<inertia ixx="0"  ixy="0"  ixz="0" iyy="0" iyz="0" izz="0" />-->
      <!-- NOTE: Assuming cylinder centered at CoM with r=0.05, h=0.05 with axis parallel to y coordinate -->
      <!-- <inertia ixx="0.0013417"  ixy="0"  ixz="0" iyy="0.0020125" iyz="0" izz="0.0013417" /> -->
      <inertia ixx="0.0046195621" ixy="-0.00056769245" ixz="0.00018376961" iyy="0.00185384237" iyz="-0.00078286958" izz="0.0049356022"/>
    </inertial>
    <visual>
      <origin rpy="0 0 0" xyz="0 0 0"/>
      <geometry>
        <mesh filename="package://reemc_description/meshes/arm/arm_2.dae" scale="1 1 -1.0"/>
      </geometry>
      <material name="DarkGrey"/>
    </visual>
    <collision>
      <origin rpy="0 0 0" xyz="0 0 0"/>
      <geometry>
        <mesh filename="package://reemc_description/meshes/arm/arm_2_collision.stl" scale="1 1 -1.0"/>
      </geometry>
    </collision>
  </link>
  <joint name="arm_right_2_joint" type="revolute">
    <parent link="arm_right_1_link"/>
    <child link="arm_right_2_link"/>
    <origin rpy="-1.57079632679 -1.308996939 1.57079632679" xyz="0 0 0.21749"/>
    <axis xyz="0 0 1"/>
    <limit effort="22.32" lower="-0.261799387799" upper="2.09439510239" velocity="3.66"/>
    <dynamics damping="0.1" friction="0.0"/>
    <safety_controller k_position="20" k_velocity="20" soft_lower_limit="-0.241799387799" soft_upper_limit="2.07439510239"/>
  </joint>
  <link name="arm_right_3_link">
    <inertial>
      <origin rpy="0 0 0" xyz="0.00606 -0.0113 0.05748"/>
      <mass value="2.070092"/>
      <!--<inertia ixx="0"  ixy="0"  ixz="0" iyy="0" iyz="0" izz="0" />-->
      <!-- NOTE: Assuming cylinder centered at CoM with r=0.05, h=0.05 with axis parallel to x coordinate -->
      <inertia ixx="0.00372686652" ixy="-0.00008722874" ixz="-0.00028800176" iyy="0.00344463026" iyz="0.00042776588" izz="0.00192229026"/>
    </inertial>
    <visual>
      <origin rpy="0 0 0" xyz="0 0 0"/>
      <geometry>
        <mesh filename="package://reemc_description/meshes/arm/arm_3.dae" scale="1 1 -1.0"/>
      </geometry>
      <material name="DarkGrey"/>
    </visual>
    <collision>
      <origin rpy="0 0 0" xyz="0 0 0"/>
      <geometry>
        <mesh filename="package://reemc_description/meshes/arm/arm_3_collision.stl" scale="1 1 -1.0"/>
      </geometry>
    </collision>
  </link>
  <joint name="arm_right_3_joint" type="revolute">
    <parent link="arm_right_2_link"/>
    <child link="arm_right_3_link"/>
    <origin rpy="1.57079632679 0 0" xyz="0.02 -0.142 0"/>
    <axis xyz="0 0 1"/>
    <limit effort="17.86" lower="-2.35619449019" upper="2.74889357189" velocity="4.58"/>
    <dynamics damping="1.0" friction="1.0"/>
    <safety_controller k_position="20" k_velocity="20" soft_lower_limit="-2.33619449019" soft_upper_limit="2.72889357189"/>
  </joint>
  <!--************************-->
  <!--        ELBOW           -->
  <!--************************-->
  <link name="arm_right_4_link">
    <inertial>
      <origin rpy="0 0 0" xyz="-0.04129 0.0118 -0.01387"/>
      <mass value="1.514797"/>
      <!--<inertia ixx="0"  ixy="0"  ixz="0" iyy="0" iyz="0" izz="0" />-->
      <!-- NOTE: Assuming cylinder centered at CoM with r=0.05, h=0.05 with axis parallel to x coordinate -->
      <!-- <inertia ixx="0.0012663"  ixy="0"  ixz="0" iyy="0.00084417" iyz="0" izz="0.00084417" /> -->
      <inertia ixx="0.00156355749" ixy="-0.000353141" ixz="0.00053402452" iyy="0.00277186194" iyz="-0.00015541973" izz="0.00307369106"/>
    </inertial>
    <visual>
      <origin rpy="0 0 0" xyz="0 0 0"/>
      <geometry>
        <mesh filename="package://reemc_description/meshes/arm/arm_4.dae" scale="1 1 -1.0"/>
      </geometry>
      <material name="DarkGrey"/>
    </visual>
    <collision>
      <origin rpy="0 0 0" xyz="0 0 0"/>
      <geometry>
        <mesh filename="package://reemc_description/meshes/arm/arm_4_collision.stl" scale="1 1 -1.0"/>
      </geometry>
    </collision>
  </link>
  <joint name="arm_right_4_joint" type="revolute">
    <parent link="arm_right_3_link"/>
    <child link="arm_right_4_link"/>
    <origin rpy="0 1.57079632679 0" xyz="0 -0.02 0.088"/>
    <axis xyz="0 0 1"/>
    <limit effort="17.86" lower="0.001" upper="2.26892802759" velocity="4.58"/>
    <dynamics damping="1.0" friction="1.0"/>
    <safety_controller k_position="20" k_velocity="20" soft_lower_limit="0.001" soft_upper_limit="2.24892802759"/>
  </joint>
  <gazebo reference="arm_right_1_link">
    <mu1>0.9</mu1>
    <mu2>0.9</mu2>
  </gazebo>
  <gazebo reference="arm_right_2_link">
    <mu1>0.9</mu1>
    <mu2>0.9</mu2>
  </gazebo>
  <gazebo reference="arm_right_3_link">
    <mu1>0.9</mu1>
    <mu2>0.9</mu2>
  </gazebo>
  <gazebo reference="arm_right_4_link">
    <mu1>0.9</mu1>
    <mu2>0.9</mu2>
  </gazebo>
  <gazebo reference="arm_right_1_joint">
    <implicitSpringDamper>1</implicitSpringDamper>
  </gazebo>
  <gazebo reference="arm_right_2_joint">
    <implicitSpringDamper>1</implicitSpringDamper>
  </gazebo>
  <gazebo reference="arm_right_3_joint">
    <implicitSpringDamper>1</implicitSpringDamper>
  </gazebo>
  <gazebo reference="arm_right_4_joint">
    <implicitSpringDamper>1</implicitSpringDamper>
  </gazebo>
  <!--************************-->
  <!--        WRIST           -->
  <!--************************-->
  <link name="arm_right_5_link">
    <inertial>
      <origin rpy="0 0 0" xyz="-0.00044 0.00012 0.07445"/>
      <mass value="1.531202"/>
      <!-- <inertia ixx="0"  ixy="0"  ixz="0" iyy="0" iyz="0" izz="0" /> -->
      <!-- NOTE: Assuming cylinder centered at CoM with r=0.05, h=0.1 with axis parallel to z coordinate -->
      <!--         <inertia ixx="0.0027096"  ixy="0"  ixz="0" iyy="0.0027096" iyz="0" izz="0.0023225" /> -->
      <inertia ixx="0.00193499547" ixy="-0.00000027528" ixz="-0.00001268153" iyy="0.00177767506" iyz="-0.00000466638" izz="0.00057101196"/>
    </inertial>
    <visual>
      <origin rpy="0 0 0" xyz="0 0 0"/>
      <geometry>
        <mesh filename="package://reemc_description/meshes/arm/arm_5.dae" scale="1 1 -1.0"/>
      </geometry>
      <material name="LightGrey"/>
    </visual>
    <collision>
      <origin rpy="0 0 0" xyz="0 0 0"/>
      <geometry>
        <mesh filename="package://reemc_description/meshes/arm/arm_5_collision.stl" scale="1 1 -1.0"/>
      </geometry>
    </collision>
  </link>
  <joint name="arm_right_5_joint" type="revolute">
    <parent link="arm_right_4_link"/>
    <child link="arm_right_5_link"/>
    <origin rpy="0 -1.57079632679 0" xyz="-0.088 0.02 0"/>
    <axis xyz="0 0 1"/>
    <limit effort="3" lower="-2.09439510239" upper="2.09439510239" velocity="1.95"/>
    <!--TODO: Check effort value!-->
    <dynamics damping="1.0" friction="1.0"/>
    <safety_controller k_position="20" k_velocity="20" soft_lower_limit="-2.07439510239" soft_upper_limit="2.07439510239"/>
  </joint>
  <link name="arm_right_6_link">
    <inertial>
      <origin rpy="0 0 0" xyz="-0.00005 -0.00252 7e-05"/>
      <mass value="0.524122"/>
      <!-- <inertia ixx="0"  ixy="0"  ixz="0" iyy="0" iyz="0" izz="0" /> -->
      <!-- NOTE: Assuming cylinder centered at CoM with r=0.02, h=0.08 with axis parallel to z coordinate -->
      <!--         <inertia ixx="0.0001615"  ixy="0"  ixz="0" iyy="0.0001615" iyz="0" izz="0.000051" /> -->
      <inertia ixx="0.00020339659" ixy="-0.00000071703" ixz="-0.00000006654" iyy="0.00015240261" iyz="0.00000014315" izz="0.0001671881"/>
    </inertial>
    <visual>
      <origin rpy="0 0 0" xyz="0 0 0"/>
      <geometry>
        <mesh filename="package://reemc_description/meshes/arm/arm_6.dae" scale="1 1 -1.0"/>
      </geometry>
      <material name="LightGrey"/>
    </visual>
    <collision>
      <origin rpy="0 0 0" xyz="0 0 0"/>
      <geometry>
        <cylinder length="0.0385" radius="0.04"/>
      </geometry>
    </collision>
  </link>
  <joint name="arm_right_6_joint" type="revolute">
    <parent link="arm_right_5_link"/>
    <child link="arm_right_6_link"/>
    <origin rpy="-1.57079632679 0 0" xyz="0 0 0.15"/>
    <axis xyz="0 0 1"/>
    <limit effort="6.6" lower="-1.41371669412" upper="1.41371669412" velocity="1.76"/>
    <dynamics damping="1.0" friction="1.0"/>
    <safety_controller k_position="20" k_velocity="20" soft_lower_limit="-1.39371669412" soft_upper_limit="1.39371669412"/>
  </joint>
  <link name="arm_right_7_link">
    <inertial>
      <!--TODO: Verify these inertial parameters-->
      <origin rpy="0 0 0" xyz="-0.00004 0 -0.02887"/>
      <mass value="0.084382"/>
      <!-- <inertia ixx="0"  ixy="0"  ixz="0" iyy="0" iyz="0" izz="0" /> -->
      <!-- NOTE: Assuming point mass -->
      <!--         <inertia ixx="0"  ixy="0"  ixz="0" iyy="0" iyz="0" izz="0" /> -->
      <inertia ixx="0.0000123718" ixy="0.00000000002" ixz="0.00000002403" iyy="0.00001242132" iyz="0.00000000001" izz="0.0000059514"/>
    </inertial>
    <visual>
      <origin rpy="0 0 0" xyz="0 0 0.046"/>
      <geometry>
        <cylinder length="0.005" radius="0.02"/>
      </geometry>
      <material name="DarkGrey"/>
    </visual>
    <collision>
      <origin rpy="0 0 0" xyz="0 0 0.0345"/>
      <geometry>
        <cylinder length="0.023" radius="0.02"/>
      </geometry>
    </collision>
  </link>
  <joint name="arm_right_7_joint" type="revolute">
    <parent link="arm_right_6_link"/>
    <child link="arm_right_7_link"/>
    <origin rpy="1.57079632679 0 0" xyz="0 0 0"/>
    <axis xyz="0 0 1"/>
    <limit effort="6.6" lower="-2.09439510239" upper="2.09439510239" velocity="1.76"/>
    <dynamics damping="1.0" friction="1.0"/>
    <safety_controller k_position="20" k_velocity="20" soft_lower_limit="-2.07439510239" soft_upper_limit="2.07439510239"/>
  </joint>
  <gazebo reference="arm_right_5_link">
    <mu1>0.9</mu1>
    <mu2>0.9</mu2>
  </gazebo>
  <gazebo reference="arm_right_6_link">
    <mu1>0.9</mu1>
    <mu2>0.9</mu2>
  </gazebo>
  <gazebo reference="arm_right_7_link">
    <mu1>0.9</mu1>
    <mu2>0.9</mu2>
  </gazebo>
  <gazebo reference="arm_right_5_joint">
    <implicitSpringDamper>1</implicitSpringDamper>
  </gazebo>
  <gazebo reference="arm_right_6_joint">
    <implicitSpringDamper>1</implicitSpringDamper>
  </gazebo>
  <gazebo reference="arm_right_7_joint">
    <implicitSpringDamper>1</implicitSpringDamper>
    <provideFeedback>1</provideFeedback>
  </gazebo>
  <transmission name="arm_right_5_trans">
    <type>transmission_interface/SimpleTransmission</type>
    <actuator name="arm_right_5_motor">
      <mechanicalReduction>1.0</mechanicalReduction>
    </actuator>
    <joint name="arm_right_5_joint">
      <hardwareInterface>hardware_interface/PositionJointInterface</hardwareInterface>
    </joint>
  </transmission>
  <transmission name="wrist_right_trans">
    <type>transmission_interface/DifferentialTransmission</type>
    <actuator name="arm_right_6_motor">
      <role>actuator1</role>
      <mechanicalReduction>-1.0</mechanicalReduction>
    </actuator>
    <actuator name="arm_right_7_motor">
      <role>actuator2</role>
      <mechanicalReduction>1.0</mechanicalReduction>
    </actuator>
    <joint name="arm_right_6_joint">
      <role>joint1</role>
      <offset>0.0</offset>
      <mechanicalReduction>-1.0</mechanicalReduction>
      <hardwareInterface>hardware_interface/PositionJointInterface</hardwareInterface>
    </joint>
    <joint name="arm_right_7_joint">
      <role>joint2</role>
      <offset>0.0</offset>
      <mechanicalReduction>-1.0</mechanicalReduction>
      <hardwareInterface>hardware_interface/PositionJointInterface</hardwareInterface>
    </joint>
  </transmission>
  <!--***********************-->
  <!--        TOOL           -->
  <!--***********************-->
  <link name="arm_right_tool_link">
    <inertial>
      <mass value="0.5"/>
      <inertia ixx="0.0" ixy="0.0" ixz="0.0" iyy="0.0" iyz="0.0" izz="0.0"/>
    </inertial>
    <visual>
      <origin rpy="0 1.57079632679 0" xyz="0.001 0 0"/>
      <geometry>
        <cylinder length="0.005" radius="0.005"/>
      </geometry>
      <material name="LightGrey"/>
    </visual>
    <collision>
      <origin rpy="0 1.57079632679 0" xyz="0.001 0 0"/>
      <geometry>
        <cylinder length="0.005" radius="0.005"/>
      </geometry>
    </collision>
  </link>
  <joint name="arm_right_tool_joint" type="fixed">
    <parent link="arm_right_7_link"/>
    <child link="arm_right_tool_link"/>
    <origin rpy="1.57079632679 -1.57079632679 0" xyz="0 0 0.046"/>
  </joint>
  <transmission name="arm_right_1_trans">
    <type>transmission_interface/SimpleTransmission</type>
    <actuator name="arm_right_1_motor">
      <mechanicalReduction>1.0</mechanicalReduction>
    </actuator>
    <joint name="arm_right_1_joint">
      <hardwareInterface>hardware_interface/PositionJointInterface</hardwareInterface>
      <hardwareInterface>hardware_interface/EffortJointInterface</hardwareInterface>
    </joint>
  </transmission>
  <transmission name="arm_right_2_trans">
    <type>transmission_interface/SimpleTransmission</type>
    <actuator name="arm_right_2_motor">
      <mechanicalReduction>1.0</mechanicalReduction>
    </actuator>
    <joint name="arm_right_2_joint">
      <hardwareInterface>hardware_interface/PositionJointInterface</hardwareInterface>
      <hardwareInterface>hardware_interface/EffortJointInterface</hardwareInterface>
    </joint>
  </transmission>
  <transmission name="arm_right_3_trans">
    <type>transmission_interface/SimpleTransmission</type>
    <actuator name="arm_right_3_motor">
      <mechanicalReduction>1.0</mechanicalReduction>
    </actuator>
    <joint name="arm_right_3_joint">
      <hardwareInterface>hardware_interface/PositionJointInterface</hardwareInterface>
      <hardwareInterface>hardware_interface/EffortJointInterface</hardwareInterface>
    </joint>
  </transmission>
  <transmission name="arm_right_4_trans">
    <type>transmission_interface/SimpleTransmission</type>
    <actuator name="arm_right_4_motor">
      <mechanicalReduction>1.0</mechanicalReduction>
    </actuator>
    <joint name="arm_right_4_joint">
      <hardwareInterface>hardware_interface/PositionJointInterface</hardwareInterface>
      <hardwareInterface>hardware_interface/EffortJointInterface</hardwareInterface>
    </joint>
  </transmission>
  <!--************************-->
  <!--        SHOULDER        -->
  <!--************************-->
  <link name="arm_left_1_link">
    <inertial>
      <origin rpy="0 0 0" xyz="0.00701 -0.00011 -0.18627"/>
      <mass value="1.935536"/>
      <!--        <inertia ixx="0"  ixy="0"  ixz="0" iyy="0" iyz="0" izz="0" /> -->
      <!--         NOTE: Assuming cylinder centered at CoM with r=0.05, h=0.05 with axis parallel to x coordinate -->
      <!--        <inertia ixx="0.0026850"  ixy="0"  ixz="0" iyy="0.0017900" iyz="0" izz="0.0017900" /> -->
      <inertia ixx="0.00327313329" ixy="-0.00000460054" ixz="-0.00025121368" iyy="0.00316047802" iyz="0.00000313158" izz="0.00157642528"/>
    </inertial>
    <visual>
      <origin rpy="0 0 0" xyz="0 0 0"/>
      <geometry>
        <mesh filename="package://reemc_description/meshes/arm/arm_1.dae" scale="1 1 1.0"/>
      </geometry>
      <material name="DarkGrey"/>
    </visual>
    <collision>
      <origin rpy="0 0 0" xyz="0 0 0"/>
      <geometry>
        <mesh filename="package://reemc_description/meshes/arm/arm_1_collision.stl" scale="1 1 1.0"/>
      </geometry>
    </collision>
  </link>
  <joint name="arm_left_1_joint" type="revolute">
    <parent link="torso_2_link"/>
    <child link="arm_left_1_link"/>
    <origin rpy="2.87979326579 0 0" xyz="0 -0.31827 0"/>
    <axis xyz="0 0 1"/>
    <limit effort="44.64" lower="-0.785398163397" upper="3.14159265359" velocity="2.7"/>
    <dynamics damping="1.0" friction="1.0"/>
    <safety_controller k_position="20" k_velocity="20" soft_lower_limit="-0.765398163397" soft_upper_limit="3.12159265359"/>
  </joint>
  <link name="arm_left_2_link">
    <inertial>
      <origin rpy="0 0 0" xyz="0.01435 -0.06294 -0.01039"/>
      <mass value="2.020952"/>
      <!--<inertia ixx="0"  ixy="0"  ixz="0" iyy="0" iyz="0" izz="0" />-->
      <!-- NOTE: Assuming cylinder centered at CoM with r=0.05, h=0.05 with axis parallel to y coordinate -->
      <!-- <inertia ixx="0.0013417"  ixy="0"  ixz="0" iyy="0.0020125" iyz="0" izz="0.0013417" /> -->
      <inertia ixx="0.0046195621" ixy="-0.00056769245" ixz="0.00018376961" iyy="0.00185384237" iyz="-0.00078286958" izz="0.0049356022"/>
    </inertial>
    <visual>
      <origin rpy="0 0 0" xyz="0 0 0"/>
      <geometry>
        <mesh filename="package://reemc_description/meshes/arm/arm_2.dae" scale="1 1 1.0"/>
      </geometry>
      <material name="DarkGrey"/>
    </visual>
    <collision>
      <origin rpy="0 0 0" xyz="0 0 0"/>
      <geometry>
        <mesh filename="package://reemc_description/meshes/arm/arm_2_collision.stl" scale="1 1 1.0"/>
      </geometry>
    </collision>
  </link>
  <joint name="arm_left_2_joint" type="revolute">
    <parent link="arm_left_1_link"/>
    <child link="arm_left_2_link"/>
    <origin rpy="1.57079632679 1.308996939 1.57079632679" xyz="0 0 -0.21749"/>
    <axis xyz="0 0 1"/>
    <limit effort="22.32" lower="-0.261799387799" upper="2.09439510239" velocity="3.66"/>
    <dynamics damping="1.0" friction="1.0"/>
    <safety_controller k_position="20" k_velocity="20" soft_lower_limit="-0.241799387799" soft_upper_limit="2.07439510239"/>
  </joint>
  <link name="arm_left_3_link">
    <inertial>
      <origin rpy="0 0 0" xyz="0.00606 -0.0113 -0.05748"/>
      <mass value="2.070092"/>
      <!--<inertia ixx="0"  ixy="0"  ixz="0" iyy="0" iyz="0" izz="0" />-->
      <!-- NOTE: Assuming cylinder centered at CoM with r=0.05, h=0.05 with axis parallel to x coordinate -->
      <inertia ixx="0.00372686652" ixy="-0.00008722874" ixz="-0.00028800176" iyy="0.00344463026" iyz="0.00042776588" izz="0.00192229026"/>
    </inertial>
    <visual>
      <origin rpy="0 0 0" xyz="0 0 0"/>
      <geometry>
        <mesh filename="package://reemc_description/meshes/arm/arm_3.dae" scale="1 1 1.0"/>
      </geometry>
      <material name="DarkGrey"/>
    </visual>
    <collision>
      <origin rpy="0 0 0" xyz="0 0 0"/>
      <geometry>
        <mesh filename="package://reemc_description/meshes/arm/arm_3_collision.stl" scale="1 1 1.0"/>
      </geometry>
    </collision>
  </link>
  <joint name="arm_left_3_joint" type="revolute">
    <parent link="arm_left_2_link"/>
    <child link="arm_left_3_link"/>
    <origin rpy="-1.57079632679 0 0" xyz="0.02 -0.142 0"/>
    <axis xyz="0 0 1"/>
    <limit effort="17.86" lower="-2.35619449019" upper="2.74889357189" velocity="4.58"/>
    <dynamics damping="1.0" friction="1.0"/>
    <safety_controller k_position="20" k_velocity="20" soft_lower_limit="-2.33619449019" soft_upper_limit="2.72889357189"/>
  </joint>
  <!--************************-->
  <!--        ELBOW           -->
  <!--************************-->
  <link name="arm_left_4_link">
    <inertial>
      <origin rpy="0 0 0" xyz="-0.04129 0.0118 0.01387"/>
      <mass value="1.514797"/>
      <!--<inertia ixx="0"  ixy="0"  ixz="0" iyy="0" iyz="0" izz="0" />-->
      <!-- NOTE: Assuming cylinder centered at CoM with r=0.05, h=0.05 with axis parallel to x coordinate -->
      <!-- <inertia ixx="0.0012663"  ixy="0"  ixz="0" iyy="0.00084417" iyz="0" izz="0.00084417" /> -->
      <inertia ixx="0.00156355749" ixy="-0.000353141" ixz="0.00053402452" iyy="0.00277186194" iyz="-0.00015541973" izz="0.00307369106"/>
    </inertial>
    <visual>
      <origin rpy="0 0 0" xyz="0 0 0"/>
      <geometry>
        <mesh filename="package://reemc_description/meshes/arm/arm_4.dae" scale="1 1 1.0"/>
      </geometry>
      <material name="DarkGrey"/>
    </visual>
    <collision>
      <origin rpy="0 0 0" xyz="0 0 0"/>
      <geometry>
        <mesh filename="package://reemc_description/meshes/arm/arm_4_collision.stl" scale="1 1 1.0"/>
      </geometry>
    </collision>
  </link>
  <joint name="arm_left_4_joint" type="revolute">
    <parent link="arm_left_3_link"/>
    <child link="arm_left_4_link"/>
    <origin rpy="0 -1.57079632679 0" xyz="0 -0.02 -0.088"/>
    <axis xyz="0 0 1"/>
    <limit effort="17.86" lower="0.001" upper="2.26892802759" velocity="4.58"/>
    <dynamics damping="1.0" friction="1.0"/>
    <safety_controller k_position="20" k_velocity="20" soft_lower_limit="0.001" soft_upper_limit="2.24892802759"/>
  </joint>
  <gazebo reference="arm_left_1_link">
    <mu1>0.9</mu1>
    <mu2>0.9</mu2>
  </gazebo>
  <gazebo reference="arm_left_2_link">
    <mu1>0.9</mu1>
    <mu2>0.9</mu2>
  </gazebo>
  <gazebo reference="arm_left_3_link">
    <mu1>0.9</mu1>
    <mu2>0.9</mu2>
  </gazebo>
  <gazebo reference="arm_left_4_link">
    <mu1>0.9</mu1>
    <mu2>0.9</mu2>
  </gazebo>
  <gazebo reference="arm_left_1_joint">
    <implicitSpringDamper>1</implicitSpringDamper>
  </gazebo>
  <gazebo reference="arm_left_2_joint">
    <implicitSpringDamper>1</implicitSpringDamper>
  </gazebo>
  <gazebo reference="arm_left_3_joint">
    <implicitSpringDamper>1</implicitSpringDamper>
  </gazebo>
  <gazebo reference="arm_left_4_joint">
    <implicitSpringDamper>1</implicitSpringDamper>
  </gazebo>
  <!--************************-->
  <!--        WRIST           -->
  <!--************************-->
  <link name="arm_left_5_link">
    <inertial>
      <origin rpy="0 0 0" xyz="-0.00044 0.00012 -0.07445"/>
      <mass value="1.531202"/>
      <!-- <inertia ixx="0"  ixy="0"  ixz="0" iyy="0" iyz="0" izz="0" /> -->
      <!-- NOTE: Assuming cylinder centered at CoM with r=0.05, h=0.1 with axis parallel to z coordinate -->
      <!--         <inertia ixx="0.0027096"  ixy="0"  ixz="0" iyy="0.0027096" iyz="0" izz="0.0023225" /> -->
      <inertia ixx="0.00193499547" ixy="-0.00000027528" ixz="-0.00001268153" iyy="0.00177767506" iyz="-0.00000466638" izz="0.00057101196"/>
    </inertial>
    <visual>
      <origin rpy="0 0 0" xyz="0 0 0"/>
      <geometry>
        <mesh filename="package://reemc_description/meshes/arm/arm_5.dae" scale="1 1 1.0"/>
      </geometry>
      <material name="LightGrey"/>
    </visual>
    <collision>
      <origin rpy="0 0 0" xyz="0 0 0"/>
      <geometry>
        <mesh filename="package://reemc_description/meshes/arm/arm_5_collision.stl" scale="1 1 1.0"/>
      </geometry>
    </collision>
  </link>
  <joint name="arm_left_5_joint" type="revolute">
    <parent link="arm_left_4_link"/>
    <child link="arm_left_5_link"/>
    <origin rpy="0 1.57079632679 0" xyz="-0.088 0.02 0"/>
    <axis xyz="0 0 1"/>
    <limit effort="3" lower="-2.09439510239" upper="2.09439510239" velocity="1.95"/>
    <!--TODO: Check effort value!-->
    <dynamics damping="1.0" friction="1.0"/>
    <safety_controller k_position="20" k_velocity="20" soft_lower_limit="-2.07439510239" soft_upper_limit="2.07439510239"/>
  </joint>
  <link name="arm_left_6_link">
    <inertial>
      <origin rpy="0 0 0" xyz="-0.00005 -0.00252 -7e-05"/>
      <mass value="0.524122"/>
      <!-- <inertia ixx="0"  ixy="0"  ixz="0" iyy="0" iyz="0" izz="0" /> -->
      <!-- NOTE: Assuming cylinder centered at CoM with r=0.02, h=0.08 with axis parallel to z coordinate -->
      <!--         <inertia ixx="0.0001615"  ixy="0"  ixz="0" iyy="0.0001615" iyz="0" izz="0.000051" /> -->
      <inertia ixx="0.00020339659" ixy="-0.00000071703" ixz="-0.00000006654" iyy="0.00015240261" iyz="0.00000014315" izz="0.0001671881"/>
    </inertial>
    <visual>
      <origin rpy="0 0 0" xyz="0 0 0"/>
      <geometry>
        <mesh filename="package://reemc_description/meshes/arm/arm_6.dae" scale="1 1 1.0"/>
      </geometry>
      <material name="LightGrey"/>
    </visual>
    <collision>
      <origin rpy="0 0 0" xyz="0 0 0"/>
      <geometry>
        <cylinder length="0.0385" radius="0.04"/>
      </geometry>
    </collision>
  </link>
  <joint name="arm_left_6_joint" type="revolute">
    <parent link="arm_left_5_link"/>
    <child link="arm_left_6_link"/>
    <origin rpy="1.57079632679 0 0" xyz="0 0 -0.15"/>
    <axis xyz="0 0 1"/>
    <limit effort="6.6" lower="-1.41371669412" upper="1.41371669412" velocity="1.76"/>
    <dynamics damping="1.0" friction="1.0"/>
    <safety_controller k_position="20" k_velocity="20" soft_lower_limit="-1.39371669412" soft_upper_limit="1.39371669412"/>
  </joint>
  <link name="arm_left_7_link">
    <inertial>
      <!--TODO: Verify these inertial parameters-->
      <origin rpy="0 0 0" xyz="-0.00004 0 0.02887"/>
      <mass value="0.084382"/>
      <!-- <inertia ixx="0"  ixy="0"  ixz="0" iyy="0" iyz="0" izz="0" /> -->
      <!-- NOTE: Assuming point mass -->
      <!--         <inertia ixx="0"  ixy="0"  ixz="0" iyy="0" iyz="0" izz="0" /> -->
      <inertia ixx="0.0000123718" ixy="0.00000000002" ixz="0.00000002403" iyy="0.00001242132" iyz="0.00000000001" izz="0.0000059514"/>
    </inertial>
    <visual>
      <origin rpy="0 0 0" xyz="0 0 -0.046"/>
      <geometry>
        <cylinder length="0.005" radius="0.02"/>
      </geometry>
      <material name="DarkGrey"/>
    </visual>
    <collision>
      <origin rpy="0 0 0" xyz="0 0 -0.0345"/>
      <geometry>
        <cylinder length="0.023" radius="0.02"/>
      </geometry>
    </collision>
  </link>
  <joint name="arm_left_7_joint" type="revolute">
    <parent link="arm_left_6_link"/>
    <child link="arm_left_7_link"/>
    <origin rpy="-1.57079632679 0 0" xyz="0 0 0"/>
    <axis xyz="0 0 1"/>
    <limit effort="6.6" lower="-2.09439510239" upper="2.09439510239" velocity="1.76"/>
    <dynamics damping="1.0" friction="1.0"/>
    <safety_controller k_position="20" k_velocity="20" soft_lower_limit="-2.07439510239" soft_upper_limit="2.07439510239"/>
  </joint>
  <gazebo reference="arm_left_5_link">
    <mu1>0.9</mu1>
    <mu2>0.9</mu2>
  </gazebo>
  <gazebo reference="arm_left_6_link">
    <mu1>0.9</mu1>
    <mu2>0.9</mu2>
  </gazebo>
  <gazebo reference="arm_left_7_link">
    <mu1>0.9</mu1>
    <mu2>0.9</mu2>
  </gazebo>
  <gazebo reference="arm_left_5_joint">
    <implicitSpringDamper>1</implicitSpringDamper>
  </gazebo>
  <gazebo reference="arm_left_6_joint">
    <implicitSpringDamper>1</implicitSpringDamper>
  </gazebo>
  <gazebo reference="arm_left_7_joint">
    <implicitSpringDamper>1</implicitSpringDamper>
    <provideFeedback>1</provideFeedback>
  </gazebo>
  <transmission name="arm_left_5_trans">
    <type>transmission_interface/SimpleTransmission</type>
    <actuator name="arm_left_5_motor">
      <mechanicalReduction>1.0</mechanicalReduction>
    </actuator>
    <joint name="arm_left_5_joint">
      <hardwareInterface>hardware_interface/PositionJointInterface</hardwareInterface>
    </joint>
  </transmission>
  <transmission name="wrist_left_trans">
    <type>transmission_interface/DifferentialTransmission</type>
    <actuator name="arm_left_6_motor">
      <role>actuator1</role>
      <mechanicalReduction>-1.0</mechanicalReduction>
    </actuator>
    <actuator name="arm_left_7_motor">
      <role>actuator2</role>
      <mechanicalReduction>1.0</mechanicalReduction>
    </actuator>
    <joint name="arm_left_6_joint">
      <role>joint1</role>
      <offset>0.0</offset>
      <mechanicalReduction>-1.0</mechanicalReduction>
      <hardwareInterface>hardware_interface/PositionJointInterface</hardwareInterface>
    </joint>
    <joint name="arm_left_7_joint">
      <role>joint2</role>
      <offset>0.0</offset>
      <mechanicalReduction>1.0</mechanicalReduction>
      <hardwareInterface>hardware_interface/PositionJointInterface</hardwareInterface>
    </joint>
  </transmission>
  <!--***********************-->
  <!--        TOOL           -->
  <!--***********************-->
  <link name="arm_left_tool_link">
    <inertial>
      <mass value="0.5"/>
      <inertia ixx="0.0" ixy="0.0" ixz="0.0" iyy="0.0" iyz="0.0" izz="0.0"/>
    </inertial>
    <visual>
      <origin rpy="0 1.57079632679 0" xyz="0.001 0 0"/>
      <geometry>
        <cylinder length="0.005" radius="0.005"/>
      </geometry>
      <material name="LightGrey"/>
    </visual>
    <collision>
      <origin rpy="0 1.57079632679 0" xyz="0.001 0 0"/>
      <geometry>
        <cylinder length="0.005" radius="0.005"/>
      </geometry>
    </collision>
  </link>
  <joint name="arm_left_tool_joint" type="fixed">
    <parent link="arm_left_7_link"/>
    <child link="arm_left_tool_link"/>
    <origin rpy="1.57079632679 1.57079632679 0" xyz="0 0 -0.046"/>
  </joint>
  <transmission name="arm_left_1_trans">
    <type>transmission_interface/SimpleTransmission</type>
    <actuator name="arm_left_1_motor">
      <mechanicalReduction>1.0</mechanicalReduction>
    </actuator>
    <joint name="arm_left_1_joint">
      <hardwareInterface>hardware_interface/PositionJointInterface</hardwareInterface>
      <hardwareInterface>hardware_interface/EffortJointInterface</hardwareInterface>
    </joint>
  </transmission>
  <transmission name="arm_left_2_trans">
    <type>transmission_interface/SimpleTransmission</type>
    <actuator name="arm_left_2_motor">
      <mechanicalReduction>1.0</mechanicalReduction>
    </actuator>
    <joint name="arm_left_2_joint">
      <hardwareInterface>hardware_interface/PositionJointInterface</hardwareInterface>
      <hardwareInterface>hardware_interface/EffortJointInterface</hardwareInterface>
    </joint>
  </transmission>
  <transmission name="arm_left_3_trans">
    <type>transmission_interface/SimpleTransmission</type>
    <actuator name="arm_left_3_motor">
      <mechanicalReduction>1.0</mechanicalReduction>
    </actuator>
    <joint name="arm_left_3_joint">
      <hardwareInterface>hardware_interface/PositionJointInterface</hardwareInterface>
      <hardwareInterface>hardware_interface/EffortJointInterface</hardwareInterface>
    </joint>
  </transmission>
  <transmission name="arm_left_4_trans">
    <type>transmission_interface/SimpleTransmission</type>
    <actuator name="arm_left_4_motor">
      <mechanicalReduction>1.0</mechanicalReduction>
    </actuator>
    <joint name="arm_left_4_joint">
      <hardwareInterface>hardware_interface/PositionJointInterface</hardwareInterface>
      <hardwareInterface>hardware_interface/EffortJointInterface</hardwareInterface>
    </joint>
  </transmission>
  <!--************************-->
  <!--        ft sensor       -->
  <!--************************-->
  <link name="wrist_right_ft_link">
    <inertial>
      <mass value="0.126"/>
      <inertia ixx="0.0" ixy="0.0" ixz="0.0" iyy="0.0" iyz="0.0" izz="0.0"/>
    </inertial>
    <visual>
      <origin rpy="0 0 0" xyz="0 0 0"/>
      <geometry>
        <cylinder length="0.0157" radius="0.0225"/>
      </geometry>
      <material name="LightGrey"/>
    </visual>
    <collision>
      <origin rpy="0 0 0" xyz="0 0 0"/>
      <geometry>
        <cylinder length="0.0157" radius="0.0225"/>
      </geometry>
    </collision>
  </link>
  <joint name="wrist_right_ft_joint" type="fixed">
    <parent link="arm_right_tool_link"/>
    <child link="wrist_right_ft_link"/>
    <origin rpy="1.57079632679 0 1.57079632679" xyz="0.00785 0 0"/>
  </joint>
  <!--***********************-->
  <!--       FT TOOL         -->
  <!--***********************-->
  <link name="wrist_right_ft_tool_link">
    <inertial>
      <mass value="0.126"/>
      <inertia ixx="0.0" ixy="0.0" ixz="0.0" iyy="0.0" iyz="0.0" izz="0.0"/>
    </inertial>
    <visual>
      <origin rpy="0 1.57079632679 0" xyz="0.0 0 0"/>
      <geometry>
        <cylinder length="0.00975" radius="0.025"/>
      </geometry>
      <material name="FlatBlack"/>
    </visual>
    <collision>
      <origin rpy="0 1.57079632679 0" xyz="0.0 0 0"/>
      <geometry>
        <cylinder length="0.00975" radius="0.025"/>
      </geometry>
    </collision>
  </link>
  <joint name="wrist_right_tool_joint" type="fixed">
    <parent link="wrist_right_ft_link"/>
    <child link="wrist_right_ft_tool_link"/>
    <origin rpy="-1.57079632679 -1.57079632679 0" xyz="0 0 0.012725"/>
  </joint>
  <!--************************-->
  <!--        ft sensor       -->
  <!--************************-->
  <link name="wrist_left_ft_link">
    <inertial>
      <mass value="0.126"/>
      <inertia ixx="0.0" ixy="0.0" ixz="0.0" iyy="0.0" iyz="0.0" izz="0.0"/>
    </inertial>
    <visual>
      <origin rpy="0 0 0" xyz="0 0 0"/>
      <geometry>
        <cylinder length="0.0157" radius="0.0225"/>
      </geometry>
      <material name="LightGrey"/>
    </visual>
    <collision>
      <origin rpy="0 0 0" xyz="0 0 0"/>
      <geometry>
        <cylinder length="0.0157" radius="0.0225"/>
      </geometry>
    </collision>
  </link>
  <joint name="wrist_left_ft_joint" type="fixed">
    <parent link="arm_left_tool_link"/>
    <child link="wrist_left_ft_link"/>
    <origin rpy="1.57079632679 0 1.57079632679" xyz="0.00785 0 0"/>
  </joint>
  <!--***********************-->
  <!--       FT TOOL         -->
  <!--***********************-->
  <link name="wrist_left_ft_tool_link">
    <inertial>
      <mass value="0.126"/>
      <inertia ixx="0.0" ixy="0.0" ixz="0.0" iyy="0.0" iyz="0.0" izz="0.0"/>
    </inertial>
    <visual>
      <origin rpy="0 1.57079632679 0" xyz="0.0 0 0"/>
      <geometry>
        <cylinder length="0.00975" radius="0.025"/>
      </geometry>
      <material name="FlatBlack"/>
    </visual>
    <collision>
      <origin rpy="0 1.57079632679 0" xyz="0.0 0 0"/>
      <geometry>
        <cylinder length="0.00975" radius="0.025"/>
      </geometry>
    </collision>
  </link>
  <joint name="wrist_left_tool_joint" type="fixed">
    <parent link="wrist_left_ft_link"/>
    <child link="wrist_left_ft_tool_link"/>
    <origin rpy="-1.57079632679 -1.57079632679 0" xyz="0 0 0.012725"/>
  </joint>
  <joint name="hand_right_palm_joint" type="fixed">
    <parent link="wrist_right_ft_tool_link"/>
    <child link="hand_right_palm_link"/>
    <origin rpy="0 0 0" xyz="0 0 0"/>
  </joint>
  <link name="hand_right_palm_link">
    <inertial>
      <origin rpy="0 0 0" xyz="0.0641 -0.0022 0.0021"/>
      <!-- NOTE: Less than total palm mass of 0.598kg because actuator masses are specified separately -->
      <mass value="0.4"/>
      <inertia ixx="0.000305100" ixy="0.000005037" ixz="0.000015302" iyy="0.000811920" iyz="0.000007622" izz="0.000655851"/>
    </inertial>
    <visual>
      <origin rpy="0 0 0" xyz="0 0 0"/>
      <geometry>
        <mesh filename="package://tum_ics_hey5_description/meshes/palm.stl" scale="1 1 1"/>
      </geometry>
      <material name="Hey5DarkGrey"/>
    </visual>
    <collision>
      <origin rpy="0 0 0" xyz="0 0 0"/>
      <geometry>
        <mesh filename="package://tum_ics_hey5_description/meshes/palm_collision.stl" scale="1 1 1"/>
      </geometry>
    </collision>
  </link>
  <gazebo reference="hand_right_palm_link">
    <material>Gazebo/Black</material>
  </gazebo>
  <!--Actuators
    <xacro:thumb_actuator parent="${name}_palm_link" name="${name}_thumb">
      <origin xyz="0 0 0" rpy="0 0 0" /> 
    </xacro:thumb_actuator>

    <xacro:index_actuator parent="${name}_palm_link" name="${name}_index">
      <origin xyz="0 0 0" rpy="0 0 0" /> 
    </xacro:index_actuator>

    <xacro:mrl_actuator parent="${name}_palm_link" name="${name}_mrl">
      <origin xyz="0 0 0" rpy="0 0 0" /> 
    </xacro:mrl_actuator>
-->
  <!--Fingers-->
  <!-- TODO: Add grasp hack? 
    <xacro:thumb parent="${name}_palm_link" name="${name}_thumb" reflect="${reflect}">
      <origin xyz="0.0901 0.0134 ${reflect * 0.038}" rpy="0 ${-reflect * 65 * deg_to_rad} 0" />
    </xacro:thumb>

    <xacro:finger parent="${name}_palm_link" name="${name}_index" reflect="${reflect}">
      <origin xyz="0.1265 0.0042 ${reflect * 0.0265}" rpy="${-reflect * 90 * deg_to_rad} ${-reflect * 30 * deg_to_rad} 0" />
    </xacro:finger>

    <xacro:finger parent="${name}_palm_link" name="${name}_middle" reflect="${reflect}">
      <origin xyz="0.1335 0.0042 ${reflect * 0.007}" rpy="${-reflect * 90 * deg_to_rad} 0 0" />
    </xacro:finger>

    <xacro:finger parent="${name}_palm_link" name="${name}_ring" reflect="${reflect}">
      <origin xyz="0.1265 0.0042 ${reflect * -0.0125}" rpy="${-reflect * 90 * deg_to_rad} ${reflect * 15 * deg_to_rad} 0" />
    </xacro:finger>

    <xacro:finger parent="${name}_palm_link" name="${name}_little" reflect="${reflect}">
      <origin xyz="0.1165 0.0042 ${reflect * -0.032}" rpy="${-reflect * 90 * deg_to_rad} ${reflect * 30 * deg_to_rad} 0" />
    </xacro:finger>
-->
  <!--Transmissions
    <xacro:thumb_transmissions
      finger_name="${name}_thumb"
      act_name="${name}_thumb_motor"
      act_flex_start="${thumb_act_flex_start}"
      jnt_abd_start="${0.0 * deg_to_rad}"
      jnt_abd_stop="${90 * deg_to_rad}"
      abd_reduction="${75 * deg_to_rad / thumb_act_flex_start}"
      flex_reduction="${40 * deg_to_rad / (360 * deg_to_rad - thumb_act_flex_start)}"
    />

    <xacro:finger_transmissions
      finger_name="${name}_index"
      act_name="${name}_index_motor"
      act_flex_start="${index_act_flex_start}"
      jnt_abd_start="${0.0 * deg_to_rad}"
      jnt_abd_stop="${30.0 * deg_to_rad}"
      abd_reduction="${20.0 * deg_to_rad / index_act_flex_start}"
      flex_reduction="${36 * deg_to_rad / (390 * deg_to_rad - index_act_flex_start)}"
    />

    <xacro:finger_transmissions
      finger_name="${name}_middle"
      act_name="${name}_mrl_motor"
      act_flex_start="${middle_act_flex_start}"
      jnt_abd_start="${0.0 * deg_to_rad}"
      jnt_abd_stop="${0.0 * deg_to_rad}"
      abd_reduction="1.0"
      flex_reduction="${36 * deg_to_rad / (530 * deg_to_rad - middle_act_flex_start)}"
    />

    <xacro:finger_transmissions
      finger_name="${name}_ring"
      act_name="${name}_mrl_motor"
      act_flex_start="${ring_act_flex_start}"
      jnt_abd_start="${-15.0 * deg_to_rad}"
      jnt_abd_stop="${0.0 * deg_to_rad}"
      abd_reduction="${-10.0 * deg_to_rad / ring_act_flex_start}"
      flex_reduction="${36 * deg_to_rad / (530 * deg_to_rad - ring_act_flex_start)}"
    />

    <xacro:finger_transmissions
      finger_name="${name}_little"
      act_name="${name}_mrl_motor"
      act_flex_start="${little_act_flex_start}"
      jnt_abd_start="${-30.0 * deg_to_rad}"
      jnt_abd_stop="${0.0 * deg_to_rad}"
      abd_reduction="${-20.0 * deg_to_rad / little_act_flex_start}"
      flex_reduction="${36 * deg_to_rad / (530 * deg_to_rad - little_act_flex_start)}"
    />
    
    -->
  <link name="hand_right_grasping_frame"/>
  <joint name="hand_right_grasping_fixed_joint" type="fixed">
    <parent link="hand_right_palm_link"/>
    <child link="hand_right_grasping_frame"/>
    <axis xyz="0 0 1"/>
    <origin rpy="0 0 0" xyz="0.13 0.02 0"/>
  </joint>
  <!-- hey5 gazebo plugin 
    <xacro:hey5_gazebo_simulation side="${name}"/> -->
  <joint name="hand_left_palm_joint" type="fixed">
    <parent link="wrist_left_ft_tool_link"/>
    <child link="hand_left_palm_link"/>
    <origin rpy="3.14159265359 0 0" xyz="0 0 0"/>
  </joint>
  <link name="hand_left_palm_link">
    <inertial>
      <origin rpy="0 0 0" xyz="0.0641 -0.0022 0.0021"/>
      <!-- NOTE: Less than total palm mass of 0.598kg because actuator masses are specified separately -->
      <mass value="0.4"/>
      <inertia ixx="0.000305100" ixy="0.000005037" ixz="0.000015302" iyy="0.000811920" iyz="0.000007622" izz="0.000655851"/>
    </inertial>
    <visual>
      <origin rpy="0 0 0" xyz="0 0 0"/>
      <geometry>
        <mesh filename="package://tum_ics_hey5_description/meshes/palm.stl" scale="1 1 -1"/>
      </geometry>
      <material name="Hey5DarkGrey"/>
    </visual>
    <collision>
      <origin rpy="0 0 0" xyz="0 0 0"/>
      <geometry>
        <mesh filename="package://tum_ics_hey5_description/meshes/palm_collision.stl" scale="1 1 -1"/>
      </geometry>
    </collision>
  </link>
  <gazebo reference="hand_left_palm_link">
    <material>Gazebo/Black</material>
  </gazebo>
  <!--Actuators
    <xacro:thumb_actuator parent="${name}_palm_link" name="${name}_thumb">
      <origin xyz="0 0 0" rpy="0 0 0" /> 
    </xacro:thumb_actuator>

    <xacro:index_actuator parent="${name}_palm_link" name="${name}_index">
      <origin xyz="0 0 0" rpy="0 0 0" /> 
    </xacro:index_actuator>

    <xacro:mrl_actuator parent="${name}_palm_link" name="${name}_mrl">
      <origin xyz="0 0 0" rpy="0 0 0" /> 
    </xacro:mrl_actuator>
-->
  <!--Fingers-->
  <!-- TODO: Add grasp hack? 
    <xacro:thumb parent="${name}_palm_link" name="${name}_thumb" reflect="${reflect}">
      <origin xyz="0.0901 0.0134 ${reflect * 0.038}" rpy="0 ${-reflect * 65 * deg_to_rad} 0" />
    </xacro:thumb>

    <xacro:finger parent="${name}_palm_link" name="${name}_index" reflect="${reflect}">
      <origin xyz="0.1265 0.0042 ${reflect * 0.0265}" rpy="${-reflect * 90 * deg_to_rad} ${-reflect * 30 * deg_to_rad} 0" />
    </xacro:finger>

    <xacro:finger parent="${name}_palm_link" name="${name}_middle" reflect="${reflect}">
      <origin xyz="0.1335 0.0042 ${reflect * 0.007}" rpy="${-reflect * 90 * deg_to_rad} 0 0" />
    </xacro:finger>

    <xacro:finger parent="${name}_palm_link" name="${name}_ring" reflect="${reflect}">
      <origin xyz="0.1265 0.0042 ${reflect * -0.0125}" rpy="${-reflect * 90 * deg_to_rad} ${reflect * 15 * deg_to_rad} 0" />
    </xacro:finger>

    <xacro:finger parent="${name}_palm_link" name="${name}_little" reflect="${reflect}">
      <origin xyz="0.1165 0.0042 ${reflect * -0.032}" rpy="${-reflect * 90 * deg_to_rad} ${reflect * 30 * deg_to_rad} 0" />
    </xacro:finger>
-->
  <!--Transmissions
    <xacro:thumb_transmissions
      finger_name="${name}_thumb"
      act_name="${name}_thumb_motor"
      act_flex_start="${thumb_act_flex_start}"
      jnt_abd_start="${0.0 * deg_to_rad}"
      jnt_abd_stop="${90 * deg_to_rad}"
      abd_reduction="${75 * deg_to_rad / thumb_act_flex_start}"
      flex_reduction="${40 * deg_to_rad / (360 * deg_to_rad - thumb_act_flex_start)}"
    />

    <xacro:finger_transmissions
      finger_name="${name}_index"
      act_name="${name}_index_motor"
      act_flex_start="${index_act_flex_start}"
      jnt_abd_start="${0.0 * deg_to_rad}"
      jnt_abd_stop="${30.0 * deg_to_rad}"
      abd_reduction="${20.0 * deg_to_rad / index_act_flex_start}"
      flex_reduction="${36 * deg_to_rad / (390 * deg_to_rad - index_act_flex_start)}"
    />

    <xacro:finger_transmissions
      finger_name="${name}_middle"
      act_name="${name}_mrl_motor"
      act_flex_start="${middle_act_flex_start}"
      jnt_abd_start="${0.0 * deg_to_rad}"
      jnt_abd_stop="${0.0 * deg_to_rad}"
      abd_reduction="1.0"
      flex_reduction="${36 * deg_to_rad / (530 * deg_to_rad - middle_act_flex_start)}"
    />

    <xacro:finger_transmissions
      finger_name="${name}_ring"
      act_name="${name}_mrl_motor"
      act_flex_start="${ring_act_flex_start}"
      jnt_abd_start="${-15.0 * deg_to_rad}"
      jnt_abd_stop="${0.0 * deg_to_rad}"
      abd_reduction="${-10.0 * deg_to_rad / ring_act_flex_start}"
      flex_reduction="${36 * deg_to_rad / (530 * deg_to_rad - ring_act_flex_start)}"
    />

    <xacro:finger_transmissions
      finger_name="${name}_little"
      act_name="${name}_mrl_motor"
      act_flex_start="${little_act_flex_start}"
      jnt_abd_start="${-30.0 * deg_to_rad}"
      jnt_abd_stop="${0.0 * deg_to_rad}"
      abd_reduction="${-20.0 * deg_to_rad / little_act_flex_start}"
      flex_reduction="${36 * deg_to_rad / (530 * deg_to_rad - little_act_flex_start)}"
    />
    
    -->
  <link name="hand_left_grasping_frame"/>
  <joint name="hand_left_grasping_fixed_joint" type="fixed">
    <parent link="hand_left_palm_link"/>
    <child link="hand_left_grasping_frame"/>
    <axis xyz="0 0 1"/>
    <origin rpy="0 0 0" xyz="0.13 0.02 0"/>
  </joint>
  <!-- hey5 gazebo plugin 
    <xacro:hey5_gazebo_simulation side="${name}"/> -->
  <joint name="stereo_frame_joint" type="fixed">
    <origin rpy="1.56293 -0.00855922 -0.0201307" xyz="0.08203  -0.0935  0.0365"/>
    <parent link="head_2_link"/>
    <child link="stereo_link"/>
  </joint>
  <!-- camera link is at center of the optical frame, but in x-forward, z-upwards and y-leftwards notation (required by gazebo to simulate a camera) -->
  <link name="stereo_link">
    <inertial>
      <mass value="0.01"/>
      <origin rpy="0 0 0" xyz="0 0 0"/>
      <inertia ixx="0" ixy="0" ixz="0" iyy="0" iyz="0" izz="0"/>
      <!-- this inertia is made up for now. -->
    </inertial>
    <visual>
      <origin rpy="0 0 0" xyz="0 0 0"/>
      <geometry>
        <box size="0.001 0.001 0.001"/>
      </geometry>
      <material name="Blue"/>
    </visual>
    <collision>
      <origin rpy="0 0 0" xyz="0 0 0"/>
      <geometry>
        <box size="0.001 0.001 0.001"/>
      </geometry>
    </collision>
  </link>
  <!-- attach optical frame to the camera link -->
  <joint name="stereo_optical_frame_joint" type="fixed">
    <origin rpy="-1.57079632679 0.0 -1.57079632679" xyz="0 0 0"/>
    <!-- rotate frame from x-forward to z-forward camera coords -->
    <parent link="stereo_link"/>
    <child link="stereo_optical_frame"/>
  </joint>
  <!-- optical frame for the stereo camera, with z-forward notation, this is the frame stereo camera images users should refer to -->
  <link name="stereo_optical_frame" type="camera">
    <inertial>
      <mass value="0.01"/>
      <origin rpy="0 0 0" xyz="0 0 0"/>
      <inertia ixx="0" ixy="0" ixz="0" iyy="0" iyz="0" izz="0"/>
      <!-- this inertia is made up for now. -->
    </inertial>
  </link>
  <joint name="stereo_gazebo_left_camera_frame_joint" type="fixed">
    <origin rpy="0.0 0.0 0.0" xyz="0 0 0"/>
    <parent link="stereo_link"/>
    <child link="stereo_gazebo_left_camera_link"/>
  </joint>
  <link name="stereo_gazebo_left_camera_link">
    <inertial>
      <mass value="0.126"/>
      <origin xyz="0 0 0"/>
      <inertia ixx="0" ixy="0.0" ixz="0.0" iyy="0" iyz="0.0" izz="0"/>
    </inertial>
    <visual>
      <origin rpy="0 1.57079632679 0" xyz="-0.01 0 0"/>
      <geometry>
        <cylinder length="0.018" radius="0.01"/>
      </geometry>
      <material name="Blue"/>
    </visual>
  </link>
  <joint name="stereo_gazebo_right_camera_frame_joint" type="fixed">
    <origin rpy="0.0 0.0 0.0" xyz="0.0 -0.073 0.0"/>
    <parent link="stereo_link"/>
    <child link="stereo_gazebo_right_camera_link"/>
  </joint>
  <link name="stereo_gazebo_right_camera_link">
    <inertial>
      <mass value="0.126"/>
      <origin xyz="0 0 0"/>
      <inertia ixx="0" ixy="0.0" ixz="0.0" iyy="0" iyz="0.0" izz="0"/>
    </inertial>
    <visual>
      <origin rpy="0 1.57079632679 0" xyz="-0.01 0 0"/>
      <geometry>
        <cylinder length="0.018" radius="0.01"/>
      </geometry>
      <material name="Blue"/>
    </visual>
  </link>
  <gazebo reference="stereo_link">
    <sensor name="gazebo_stereo_camera" type="multicamera">
      <update_rate>25.0</update_rate>
      <camera name="left">
        <horizontal_fov>1.23918376892</horizontal_fov>
        <image>
          <width>659 </width>
          <height> 493</height>
          <format>B8G8R8</format>
        </image>
        <clip>
          <near>0.01</near>
          <far>100</far>
        </clip>
      </camera>
      <camera name="right">
        <pose>0 -0.073 0 0 0 0</pose>
        <!-- the pose is wrt /stereo_link which is the parent of stereo_optical_frame -->
        <horizontal_fov>1.23918376892</horizontal_fov>
        <image>
          <width>659 </width>
          <height> 493</height>
          <format>B8G8R8</format>
        </image>
        <clip>
          <near>0.01</near>
          <far>100</far>
        </clip>
      </camera>
      <plugin filename="libgazebo_ros_multicamera.so" name="stereo_camera_controller">
        <alwaysOn>true</alwaysOn>
        <updateRate>25.0</updateRate>
        <cameraName>stereo</cameraName>
        <imageTopicName>image</imageTopicName>
        <cameraInfoTopicName>camera_info</cameraInfoTopicName>
        <frameName>stereo_optical_frame</frameName>
        <hackBaseline>0.073</hackBaseline>
        <CxPrime>330.0</CxPrime>
        <Cx>330.0</Cx>
        <Cy>247.0</Cy>
        <focalLength>461.943804</focalLength>
        <!-- image_width / (2*tan(hfov_radian /2)) -->
        <distortionK1>0.0</distortionK1>
        <distortionK2>0.0</distortionK2>
        <distortionK3>0.0</distortionK3>
        <distortionT1>0.0</distortionT1>
        <distortionT2>0.0</distortionT2>
      </plugin>
    </sensor>
  </gazebo>
  <joint name="back_camera_frame_joint" type="fixed">
    <origin rpy="-1.57079632679 0 3.14159265359" xyz="-0.128 -0.317 0"/>
    <parent link="torso_2_link"/>
    <child link="back_camera_link"/>
  </joint>
  <!-- camera link is at center of the optical frame, but in x-forward, z-upwards and y-leftwards notation (required by gazebo to simulate a camera) -->
  <link name="back_camera_link">
    <inertial>
      <mass value="0.05"/>
      <origin rpy="0 0 0" xyz="0 0 0"/>
      <inertia ixx="0.01" ixy="0" ixz="0" iyy="0.01" iyz="0" izz="0.01"/>
      <!-- this inertia is made up for now. -->
    </inertial>
    <visual>
      <origin rpy="0 0 0" xyz="0 0 0"/>
      <geometry>
        <box size="0.001 0.001 0.001"/>
      </geometry>
    </visual>
    <collision>
      <origin rpy="0 0 0" xyz="0 0 0"/>
      <geometry>
        <box size="0.001 0.001 0.001"/>
      </geometry>
    </collision>
  </link>
  <!-- attach optical frame to the camera link -->
  <joint name="back_camera_optical_frame_joint" type="fixed">
    <origin rpy="-1.57079632679 0.0 -1.57079632679" xyz="0 0 0"/>
    <!-- rotate frame from x-forward to z-forward camera coords -->
    <parent link="back_camera_link"/>
    <child link="back_camera_optical_frame"/>
  </joint>
  <!-- optical frame for the back camera, with z-forward notation, this is the frame back camera images users should refer to -->
  <link name="back_camera_optical_frame" type="camera">
    <inertial>
      <mass value="0.05"/>
      <inertia ixx="0" ixy="0" ixz="0" iyy="0" iyz="0" izz="0"/>
    </inertial>
  </link>
  <joint name="back_camera_gazebo_back_camera_frame_joint" type="fixed">
    <origin rpy="0.0 0.0 0.0" xyz="0 0 0"/>
    <parent link="back_camera_link"/>
    <child link="back_camera_gazebo_back_camera_link"/>
  </joint>
  <link name="back_camera_gazebo_back_camera_link">
    <inertial>
      <mass value="0.126"/>
      <origin xyz="0 0 0"/>
      <inertia ixx="0" ixy="0.0" ixz="0.0" iyy="0" iyz="0.0" izz="0"/>
    </inertial>
    <visual>
      <origin rpy="0 1.57079632679 0" xyz="-0.01 0 0"/>
      <geometry>
        <cylinder length="0.02" radius="0.01"/>
      </geometry>
      <material name="Blue"/>
    </visual>
  </link>
  <gazebo reference="back_camera_link">
    <sensor name="gazebo_back_camera_camera" type="camera">
      <update_rate>15.0</update_rate>
      <camera>
        <horizontal_fov>1.57078675232</horizontal_fov>
        <image>
          <width>752 </width>
          <height> 480</height>
          <format>B8G8R8</format>
        </image>
        <clip>
          <near>0.01</near>
          <far>100</far>
        </clip>
      </camera>
      <plugin filename="libgazebo_ros_camera.so" name="monocular_camera_controller">
        <alwaysOn>true</alwaysOn>
        <updateRate>15.0</updateRate>
        <cameraName>back_camera</cameraName>
        <imageTopicName>image</imageTopicName>
        <cameraInfoTopicName>camera_info</cameraInfoTopicName>
        <frameName>back_camera_optical_frame</frameName>
        <hackBaseline>0</hackBaseline>
        <CxPrime>376.5</CxPrime>
        <Cx>376.5</Cx>
        <Cy>240.5</Cy>
        <focalLength>376.002379</focalLength>
        <!-- image_width / (2*tan(hfov_radian /2)) -->
        <distortionK1>0.0</distortionK1>
        <distortionK2>0.0</distortionK2>
        <distortionK3>0.0</distortionK3>
        <distortionT1>0.0</distortionT1>
        <distortionT2>0.0</distortionT2>
      </plugin>
    </sensor>
  </gazebo>
  <link name="imu_link">
    <inertial>
      <mass value="0.01"/>
      <origin xyz="0 0 0"/>
      <inertia ixx="0.000001" ixy="0" ixz="0" iyy="0.000001" iyz="0" izz="0.000001"/>
    </inertial>
    <visual>
      <origin rpy="0 0 0" xyz="0 0 0"/>
      <geometry>
        <box size="0.01 0.01 0.01"/>
      </geometry>
    </visual>
  </link>
  <joint name="imu_joint" type="fixed">
    <origin rpy="3.14159265359 0 0" xyz="0 0 0"/>
    <parent link="base_link"/>
    <child link="imu_link"/>
  </joint>
</robot>
